Workbook

Sheet E
A1: ZM:5:0 | D1: Memory Zone output -> Entity name Période : 0
A2: VS:19:0 | D2: SYSTEM ZONE -> Balance sheet date period 0 Period : 0
A3: VS:21:0 | D3: SYSTEM ZONE -> Redactor of active document Period : 0
A4: VS:20:0 | D4: SYSTEM ZONE -> Reference active document Period : 0

Sheet S

Sheet D

Sheet MzOfficeConfig-UNDO-%ù-%ù-%ù

Sheet JET - overview
B2: Client: | C2: 파타고니아코리아 (주) (Patagonia Korea) | E2: Reference: | F2: JET
B3: Year end: | C3: 2026-04-30 | E3: Prepared by: | F3: HSH
E4: Date: | F4: 2026-06-15
E5: Reviewed by: | F5: LJM
E6: Date: | F6: 2026-06-20
B8: Journal Entries Testing
B9: MAM Tool version March 2025
B11: Please refer to the MAM Application guidance on Journal Entries Testing.
B12: Objectives
B13: In the context of ISA 330§20 and ISA 240 and in order to respond to the risk of management override of controls, to obtain sufficient, appropriate audit evidence over the appropriateness of journal entries in the nominal ledger and other adjustments made in the preparation of the financial statements. In the context of ISA 240 and in order to specifically respond to the risk of management override of controls, to obtain sufficient appropriate audit evidence that the journal entries and other adjustements made during the year/period under review are appropriate and did not indicate a potential fraud.
B14: Procedures performed + reference
K15: Reference:
B17: STEP 1 - IPE | C17: Perform procedures to ensure that the population of journal entries and other adjustments is accurate and complete | K17: JET - Step 1 '!A1
B19: STEP 2 - ISA 330 | C19: a) Determine the period of preparation of the financial statements b) Select and test the material journal entries and other adjustments made during the course of preparing the financial statements (ISA 330.20.b) | K19: JET - Step 2 (ISA 330)'!A1
B21: STEP 3 - ISA 240 | C21: a) Make inquiries of individuals involved in the financial reporting process about inappropriate or unusual activity relating the processing of journal entries and other adjustments (ISA 240.33.a.i) b) Assess the risk of a material misstatement due to fraud c) Determine the 'reporting period' d) Select and test journal entries and other adjustments made at the end of a reporting period and consider the need to select and test journal entries and other adjustments throughout the period (ISA 240.33.a.ii&iii) | K21: JET - Step 3 (ISA 240)'!A1
B25: Conclusion
B27: Step 1~3 수행 결과, 경영진의 통제 무력화 또는 부정을 시사하는 부적절하거나 비정상적인 분개는 식별되지 않았으며, 회계원장(GL) 모집단의 완전성·정확성이 확인됨. 따라서 분개테스트의 목적이 달성되었음. (Based on the work performed in Steps 1-3, no inappropriate or unusual journal entries indicative of management override of controls or fraud were identified; the objective is met.) | K27: TO BE CHANGED BY USER IF NECESSARY.

Sheet JET - Step 1 
B2: Client: | C2: ='JET - overview'!C2 | E2: Reference: | F2: ='JET - overview'!F2
B3: Year end: | C3: ='JET - overview'!C3 | E3: Prepared by: | F3: ='JET - overview'!F3
E4: Date: | F4: ='JET - overview'!F4
E5: Reviewed by: | F5: ='JET - overview'!F5
E6: Date: | F6: ='JET - overview'!F6
B10: STEP 1: Perform procedures to ensure that the population of journal entries and other adjustments is accurate and complete
B12: Accuracy and completeness of the listing of journal entries and adjustments ("JE listing")
B14: We have documented the work on ensuring accuracy and completeness of the JE listing in the MAM Tool IPE scoping and working paper | H14: GL 전체 다운로드(회계원장) / IPE scoping & 본 조서
B16: [IPE - JE listing의 완전성 및 정확성]
B17: 회사의 회계시스템에서 당기 회계연도(FY2026, 2025-05-01 ~ 2026-04-30) 전체 회계원장(General Ledger)을 계정별 라인단위로 입수함. 입수한 모집단의 완전성·정확성을 다음과 같이 확인함: (1) 차변 합계 = 대변 합계 = 730,340,479,150원으로 대차 일치(차이 0) → 복식부기 무결성 확인. (2) 총 분개라인 98,977건, 계정과목 187개, 회계기간 2025-05-01 ~ 2026-04-30 (12개월) 전 기간 연속 계상 확인. (3) 기말 잔액을 시산표(TB) 및 재무제표(FS)와 대사하여 일치함을 확인함. (4) GL 필드: 계정코드·계정명·날짜·적요·거래처명·사업자번호·차변·대변·잔액. 단, GL에는 전표번호(booking reference), 작성자/승인자/검토자/전기자(GL posting user) 및 시스템 감사증적(audit trail) 정보가 포함되어 있지 않음. 해당 항목이 필요한 경우(예외사항 발견 시) ERP 시스템 감사증적을 통해 별도 입수하여야 함.

Sheet JET - Step 2 (ISA 330)
B2: Client: | C2: ='JET - overview'!C2 | E2: Reference: | F2: ='JET - overview'!F2
B3: Year end: | C3: ='JET - overview'!C3 | E3: Prepared by: | F3: ='JET - overview'!F3
E4: Date: | F4: ='JET - overview'!F4
E5: Reviewed by: | F5: ='JET - overview'!F5
E6: Date: | F6: ='JET - overview'!F6
B9: STEP 2: a) Determine the period of preparation of the financial statements b) Select and test the material journal entries and other adjustments made during the course of preparing the financial statements (ISA 330.20.b)
B11: Selection criteria / Audit procedures
A13: 2a. | B13: We determined the period of preparation of the financial statements
B15: (i) Preparing the financial statements
B16: Start date | C16: 2025-05-01
B17: End date | C17: 2026-04-30
B21: (ii) Define the type of entries that are "journal entries / other adjustments made during the course of preparing the financial statements"
B22: 회사는 월 단위(월말) 결산을 수행하며, 재무제표 작성과정에서 계상되는 분개('journal entries / other adjustments')에는 다음이 포함됨: ① 월별 정기 결산분개(감가상각, 각종 충당금 설정, 본사 Franchise agreement에 따른 월별 VFF 정산 등) ② 기말(2026-04-30자) 결산·재분류 분개 ③ 감사조정분개(FY26 감사조정사항: 계정 재분류 등) GL에는 전표번호가 별도 부여되어 있지 않아 분개는 계정별 라인단위로 식별하였으며, 적요·계정·시점·금액을 근거로 유의적 분개를 선별함.
B32: Document results of journal entries and other adjustments testing
A34: 2b. | B34: - Test 100% of the entries above PM; and
B35: - Consider if qualitative factors for the selection of entries below PM on a judgemental basis apply
B37: [성과중요성(PM) 초과 분개 - 전수 테스트] ※ PM 금액은 감사팀이 확정하여 입력(아래 선별 분개는 어떠한 합리적 PM 기준으로도 초과하는 유의적 분개임).
J39: In case exeptions are noted:
B40: Date of journal / adjustment | C40: Booking reference | D40: Type of journal / adjustment | E40: Description of transaction | G40: Amount Currency | H40: Reference to supporting documentation | I40: Exception noted? (Yes/No) | J40: Approver / Date of approval | K40: Preparer / Date of preparation | L40: Reviewer / Date of review | M40: Individual who posts to GL/ Date of posting | N40: Follow up
B41: Entries above PM
B42: 2026-04-30 | C42: - | D42: 수기(감사조정) | E42: (800000)VFF model income — FY26 감사조정사항_VFF 계정 Reclass (영업외→판관) | G42: 34966850055 | H42: Tax 조서 .1 / 세무조정 | I42: No
B43: 2026-01-28 | C43: - | D43: 수기 | E43: (251001)외상매입금_외화(본사) — 20260128 VFF(Sep,Oct,Nov) 정산 $11,129,418 | G43: 16057292692 | H43: 매입/VFF 명세 | I43: No
B44: 2026-01-28 | C44: - | D44: 수기 | E44: (100010)HSBC USD — 미국본사 송금 및 외화 구매/환전 ($9,741,390 @1,425.93) | G44: 13890541283 | H44: 외화·자금거래 명세 | I44: No
B45: 2025-05-01 | C45: - | D45: 수기(제거) | E45: (185500)Operating ROU Asset — FY25 US 리스분개 제거분개 reverse | G45: 10762030712 | H45: 리스 조서 | I45: No
B46: 2026-04-30 | C46: - | D46: 수기(제거) | E46: (185510)ROU Asset Accum — FY26 US 리스분개 제거분개 | G46: 7984693312 | H46: 리스 조서 | I46: No
B47: 2026-04-22 | C47: - | D47: 수기 | E47: (251001)외상매입금_외화(본사) — 20260422 VFF(Jan,Feb,Mar) 정산 $5,366,919 | G47: 7785349545 | H47: 매입/VFF 명세 | I47: No
B48: 2025-12-26 | C48: - | D48: 자금이체 | E48: (100010)KEB — Internal cash transfer to KEB(704) | G48: 7000000000 | H48: 자금거래 명세 | I48: No
B49: 2025-11-30 | C49: - | D49: 수기 | E49: (251001)외상매입금_외화(본사) — 11월 VFF (Operation income, Revenue×3%) | G49: 6168340778 | H49: 매입/VFF 명세 | I49: No
B50: 2025-11-25 | C50: - | D50: 자금이체 | E50: (100010)KEB — Internal cash transfer to KEB(704) | G50: 6100000000 | H50: 자금거래 명세 | I50: No
B51: Entries with qualitative factors applied
B52: Qualitative factor 1 - 임시·미결산 성격 계정(잡손익)으로의 대체분개 (PM 미만이나 부정·오류 위험 고려)
B53: 2025-08-01 | C53: - | D53: 수기 | E53: (740040)잡이익 — 롯데부산점 공사비용 일부 보상의 건 | G53: 7400000 | H53: 증빙(입금) | I53: No
B54: 2025-11-05 | C54: - | D54: 수기 | E54: (740040)잡이익 — 출산급여 입금(노동부) | G54: 6300000 | H54: 증빙(입금) | I54: No
B55: 2026-03-31 | C55: - | D55: 수기 | E55: (740040)잡이익 — 가로수길 AR 오류 수정 | G55: 3600600 | H55: 증빙/AR 명세 | I55: No
B56: 2026-03-31 | C56: - | D56: 수기 | E56: (740040)잡이익 — 가로수길 카드결제 수선비 미반영(FY26 이전분) | G56: 2892000 | H56: 증빙 | I56: No
B57: 2025-11-10 | C57: - | D57: 수기 | E57: (740040)잡이익 — 통신서비스 변경에 따른 영업지원비 | G57: 2200000 | H57: 증빙 | I57: No
B58: 2026-04-15 | C58: - | D58: 수기 | E58: (740040)잡이익 — 스타필드고양점 정전사고 영업배상금 입금 | G58: 1649000 | H58: 증빙(입금) | I58: No
B60: Qualitative factor 2 - 비경상·미사용(seldom-used) 계정 분개 (연중 사용빈도 극히 낮음)
B61: 2025-05-31 | C61: - | D61: 수기 | E61: (730051)파생상품거래손실 — NFD Hedge 5월 (USD -276,953) | G61: 382583282 | H61: 파생상품 조서 | I61: No
B62: 2026-04-01 | C62: - | D62: 수기 | E62: (184010)소프트웨어_내부개발 — 고정자산 처분 리스트 정리 | G62: 146500000 | H62: 유형자산 조서 | I62: No
...

Sheet JET - Step 3 (ISA 240)
B2: Client: | C2: ='JET - overview'!C2 | E2: Reference: | F2: ='JET - overview'!F2 | Q2: are
B3: Year end: | C3: ='JET - overview'!C3 | E3: Prepared by: | F3: ='JET - overview'!F3 | Q3: are not
E4: Date: | F4: ='JET - overview'!F4
E5: Reviewed by: | F5: ='JET - overview'!F5
E6: Date: | F6: ='JET - overview'!F6
B9: STEP 3: a) Make inquiries of inviduals involved in the financial reporting process about inappropriate or unusual activity relating the processing of journal entries and other adjustments (ISA 240.33.a.i) b) Assess the risk of a material misstatement due to fraud c) Determine the 'end reporting the period' d) Select and test journal entries and other adjustments made at the end of a reporting period and consider the need to select and test journal entries and other adjustments throughout the period (ISA 240.33.a.ii&iii)
A11: 3a. | B11: Inquiry of management
B13: 재무보고 과정에 관여하는 [재무팀장/회계담당자 성명·직위 입력]에게 분개처리와 관련한 부적절하거나 비경상적인 활동에 대해 질문함. 질문 결과, 부적절한 분개 또는 경영진의 통제 무력화를 시사하는 정황은 파악되지 않았으며, 결산·감사조정분개는 재무팀 검토 및 본사(VF) 보고체계를 거쳐 처리됨을 확인함.
A15: 3b. | B15: Assessment of risks of material misstatement due to fraud In addition to inquiry as noted in points 3.a above, the engagement team is required to assess the risks of material misstatement due to fraud. Should the engagement team identify fraud risk factors or gather other relevant information during their assessment, the engagement team should make reference to the respective working papers and make use of such information to identify specific classes of journal entries and other adjustments for the purpose of more specific testing. Where there is no indication of any fraud risk factors and the engagement did not come across other particular information to point them towards any inappropriate or unusual activity, please state so and proceed to perform other designed audit procedures for the purpose of this working paper template.
B16: In addition to inquiry as noted in points 3.a above, the engagement team is required to assess the risks of material misstatement due to fraud. Should the engagement team identify fraud risk factors or gather other relevant information during their assessment, the engagement team should make reference to the respective working papers and make use of such information to identify specific classes of journal entries and other adjustments for the purpose of more specific testing. Where there is no indication of any fraud risk factors and the engagement did not come across other particular information to point them towards any inappropriate or unusual activity, please state so and proceed to perform other designed audit procedures for the purpose of this working paper template.
B18: 부정위험평가 조서(Fraud risk assessment) 참조
A21: 3c. | B21: Determine the 'end of a reporting period'
B22: There may be more than one reporting period. If this is the case, expand rows 28 to 39 and complete the information where appropriate.
B24: Year-end reporting
B25: Start date | C25: 2025-05-01
B26: End date | C26: 2026-04-30
B28: Semi-annual reporting
B29: Start date
B30: End date
B32: Quarter-end reporting
B33: Start date
B34: End date
B36: Month-end reporting
B37: Start date | C37: 매월 1일
B38: End date | C38: 매월 말일
A47: 3d. | B47: Select and test journal entries and other adjustments made at the end of a reporting period and consider the need to select and test journal entries and other adjustments throughout the period (ISA 240.33.a.ii&iii)
B49: Population of journal entries and other adjustments made at the end of a reporting period and throughout the period (ISA 240.33.a.ii&iii)
B50: We selected journal entries and other adjustments from the population per Step 3 for testing based on the characteristics identified below
H51: Refer to "Decision Tree - step 3" tab for more details
I52: If yes | J52: If no
B53: Fraud risk criteria | D53: Justify the selection of the fraud risk criteria | F53: Limited to JE and adjustments made at the end of a reporting period? (Yes/No + why) | H53: Do you think you have false positives in your selection? (entries which you do not consider to be fraud risk related?) (Yes/No) | I53: Justify why the criteria used are not indicative for a fraud risk. | J53: Is the individual JE already explicitly tested in the normal course of the audit? If yes -> no further procedures required If no -> test ALL identified JE below | K53: Reference to testing procedures in the normal course of the audit.
B54: ① 기말/결산시점 수기 결산·재분류·감사조정 분개 (계정 대체·reclass) | D54: 결산·감사조정 과정에서 경영진 판단이 개입되어 통제 무력화 위험이 높음 | F54: Yes | H54: No | J54: 일부는 관련 계정 실증절차에서 테스트됨 → 미테스트 항목 전수 테스트
B55: ② 비경상·미사용(seldom-used) 계정으로의 분개 (전기오류수정·유형자산처분손실·파생상품손실·영업권 등) | D55: 연중 사용빈도가 극히 낮은 계정은 비정상 분개의 은닉 통로가 될 수 있음 | F55: No | H55: No | J55: No → 식별 분개 전수 테스트
B56: ③ 임시·미결산 성격 계정(잡손실·잡이익) 대체분개 | D56: 손익 조정 목적의 임시계정 이용 가능성 고려 | F56: No | H56: No | J56: No → 식별 분개 전수 테스트
B57: ④ 매출/VFF·충당금 등 유의계정에 대한 기말 조정분개 | D57: 수익인식 및 추정치 조작 위험 고려(ISA 240 수익 추정 부정위험) | F57: Yes | H57: No | J57: 관련 회계추정치 조서(B1-3·C-4·Tax·N2)와 연계 테스트
B68: Document results of journal entries and other adjustments testing
B70: Entries identified in Step 3 | I70: In case exeptions are noted:
B71: Date of journal / adjustment | C71: Booking reference | D71: Type of journal / adjustment | E71: Description of transaction | F71: Amount | G71: Reference to supporting documentation | H71: Exception noted? (Yes/No) | I71: Preparer / Date of preparation | J71: Reviewer / Date of review | K71: Approver / Date of approval | L71: Individual who posts to GL/ Date of posting | M71: Follow up
B72: 2026-04-30 | C72: - | D72: 감사조정 | E72: (800000)VFF model income — FY26 감사조정사항_VFF Reclass (영업외→판관) | F72: 34966850055 | G72: Tax .1 / 세무조정 | H72: No
B73: 2026-04-30 | C73: - | D73: 결산(제거) | E73: (185510)ROU Asset Accum — FY26 US 리스분개 제거분개 | F73: 7984693312 | G73: 리스 조서 | H73: No
...

Sheet Decision Tree - step 3
B2: Decision tree relating to step 3:

Sheet Do not delete - Tickmarks
E1: Tickmarks
A3: {a} | K3: {a}
A5: {b} | K5: {b}
A7: {c} | K7: {c}
