Workbook

Sheet 요약
A1: VRP 구조조정충당부채 GL 정리 (2026.01~09)
A2: 출처: 010_General_ledger 2026 Q1~Q3 (금액 ×100 환산), BSPL2026. 충당부채 계정 38160000(VRP)·42910311(전직지원)은 정산표상 미지급비용, 전입/환입 70051000은 판관비-급여로 매핑. 금액 차변(+)/대변(-).
A4: 1. 계정별 롤포워드 (GL 기준, BSPL과 대사)
A5: 계정 | B5: 기초(2025.12) | C5: 설정 | D5: 환입 | E5: 사용 | F5: 재분류 | G5: 역분개(순0) | H5: 기말(GL) | I5: BSPL 9월말 | J5: 차이
A6: 38160000 구조조정충당부채-VRP (미지급비용) | B6: -16873571611 | C6: =SUMIFS(분개상세!$N$2:$N$101,분개상세!$I$2:$I$101,38160000,분개상세!$M$2:$M$101,"설정") -> -1542939634 | D6: =SUMIFS(분개상세!$N$2:$N$101,분개상세!$I$2:$I$101,38160000,분개상세!$M$2:$M$101,"환입") -> 2854753560 | E6: =SUMIFS(분개상세!$N$2:$N$101,분개상세!$I$2:$I$101,38160000,분개상세!$M$2:$M$101,"사용") -> 11088573298 | F6: =SUMIFS(분개상세!$N$2:$N$101,분개상세!$I$2:$I$101,38160000,분개상세!$M$2:$M$101,"재분류(전기전표 역분개)") -> 0 | G6: =SUMIFS(분개상세!$N$2:$N$101,분개상세!$I$2:$I$101,38160000,분개상세!$M$2:$M$101,"기표 후 역분개") -> 0 | H6: =SUM(B6:G6) -> -4473184387 | I6: -4473184387 | J6: =H6-I6 -> 0
A7: 42910311 구조조정충당부채-전직지원 (미지급비용) | B7: -122500000 | C7: =SUMIFS(분개상세!$N$2:$N$101,분개상세!$I$2:$I$101,42910311,분개상세!$M$2:$M$101,"설정") -> -14000000 | D7: =SUMIFS(분개상세!$N$2:$N$101,분개상세!$I$2:$I$101,42910311,분개상세!$M$2:$M$101,"환입") -> 84000000 | E7: =SUMIFS(분개상세!$N$2:$N$101,분개상세!$I$2:$I$101,42910311,분개상세!$M$2:$M$101,"사용") -> 10500000 | F7: =SUMIFS(분개상세!$N$2:$N$101,분개상세!$I$2:$I$101,42910311,분개상세!$M$2:$M$101,"재분류(전기전표 역분개)") -> 0 | G7: =SUMIFS(분개상세!$N$2:$N$101,분개상세!$I$2:$I$101,42910311,분개상세!$M$2:$M$101,"기표 후 역분개") -> 0 | H7: =SUM(B7:G7) -> -42000000 | I7: -42000000 | J7: =H7-I7 -> 0
A8: 합계 | B8: =B6+B7 -> -16996071611 | C8: =C6+C7 -> -1556939634 | D8: =D6+D7 -> 2938753560 | E8: =E6+E7 -> 11099073298 | F8: =F6+F7 -> 0 | G8: =G6+G7 -> 0 | H8: =H6+H7 -> -4515184387 | I8: =I6+I7 -> -4515184387 | J8: =J6+J7 -> 0
A10: 2. 프로그램별 롤포워드 (38160000 + 42910311, 대변(-) = 부채)
A11: 프로그램 | B11: 기초(2025.12) | C11: 설정 | D11: 환입 | E11: 사용 | F11: 재분류 | G11: 기말(GL) | H11: 비고
A12: '25 Drive 2 (commercial) | B12: =-16873571611-122500000+3500000+3500000 -> -16989071611 | C12: =SUMIFS(분개상세!$N$2:$N$101,분개상세!$I$2:$I$101,38160000,분개상세!$L$2:$L$101,"'25 Drive 2 (commercial)",분개상세!$M$2:$M$101,"설정")+SUMIFS(분개상세!$N$2:$N$101,분개상세!$I$2:$I$101,42910311,분개상세!$L$2:$L$101,"'25 Drive 2 (commercial)",분개상세!$M$2:$M$101,"설정") -> 0 | D12: =SUMIFS(분개상세!$N$2:$N$101,분개상세!$I$2:$I$101,38160000,분개상세!$L$2:$L$101,"'25 Drive 2 (commercial)",분개상세!$M$2:$M$101,"환입")+SUMIFS(분개상세!$N$2:$N$101,분개상세!$I$2:$I$101,42910311,분개상세!$L$2:$L$101,"'25 Drive 2 (commercial)",분개상세!$M$2:$M$101,"환입") -> 2348351872 | E12: =SUMIFS(분개상세!$N$2:$N$101,분개상세!$I$2:$I$101,38160000,분개상세!$L$2:$L$101,"'25 Drive 2 (commercial)",분개상세!$M$2:$M$101,"사용")+SUMIFS(분개상세!$N$2:$N$101,분개상세!$I$2:$I$101,42910311,분개상세!$L$2:$L$101,"'25 Drive 2 (commercial)",분개상세!$M$2:$M$101,"사용") -> 11095573298 | F12: =SUMIFS(분개상세!$N$2:$N$101,분개상세!$I$2:$I$101,38160000,분개상세!$L$2:$L$101,"'25 Drive 2 (commercial)",분개상세!$M$2:$M$101,"재분류(전기전표 역분개)")+SUMIFS(분개상세!$N$2:$N$101,분개상세!$I$2:$I$101,42910311,분개상세!$L$2:$L$101,"'25 Drive 2 (commercial)",분개상세!$M$2:$M$101,"재분류(전기전표 역분개)") -> 0 | G12: =SUM(B12:F12) -> -3545146441 | H12: 기초 전액을 '25 Drive 2로 가정(전직지원 중 '24 Drive 3.5백만원, '26 Argos 3.5백만원 차감)
A13: '24 Drive | B13: -3500000 | C13: =SUMIFS(분개상세!$N$2:$N$101,분개상세!$I$2:$I$101,38160000,분개상세!$L$2:$L$101,"'24 Drive",분개상세!$M$2:$M$101,"설정")+SUMIFS(분개상세!$N$2:$N$101,분개상세!$I$2:$I$101,42910311,분개상세!$L$2:$L$101,"'24 Drive",분개상세!$M$2:$M$101,"설정") -> 0 | D13: =SUMIFS(분개상세!$N$2:$N$101,분개상세!$I$2:$I$101,38160000,분개상세!$L$2:$L$101,"'24 Drive",분개상세!$M$2:$M$101,"환입")+SUMIFS(분개상세!$N$2:$N$101,분개상세!$I$2:$I$101,42910311,분개상세!$L$2:$L$101,"'24 Drive",분개상세!$M$2:$M$101,"환입") -> 0 | E13: =SUMIFS(분개상세!$N$2:$N$101,분개상세!$I$2:$I$101,38160000,분개상세!$L$2:$L$101,"'24 Drive",분개상세!$M$2:$M$101,"사용")+SUMIFS(분개상세!$N$2:$N$101,분개상세!$I$2:$I$101,42910311,분개상세!$L$2:$L$101,"'24 Drive",분개상세!$M$2:$M$101,"사용") -> 3500000 | F13: =SUMIFS(분개상세!$N$2:$N$101,분개상세!$I$2:$I$101,38160000,분개상세!$L$2:$L$101,"'24 Drive",분개상세!$M$2:$M$101,"재분류(전기전표 역분개)")+SUMIFS(분개상세!$N$2:$N$101,분개상세!$I$2:$I$101,42910311,분개상세!$L$2:$L$101,"'24 Drive",분개상세!$M$2:$M$101,"재분류(전기전표 역분개)") -> 0 | G13: =SUM(B13:F13) -> 0 | H13: 전직지원 3월 재분류(68063200 → 42910311)
A14: '26 Fit for purpose | B14: 0 | C14: =SUMIFS(분개상세!$N$2:$N$101,분개상세!$I$2:$I$101,38160000,분개상세!$L$2:$L$101,"'26 Fit for purpose",분개상세!$M$2:$M$101,"설정")+SUMIFS(분개상세!$N$2:$N$101,분개상세!$I$2:$I$101,42910311,분개상세!$L$2:$L$101,"'26 Fit for purpose",분개상세!$M$2:$M$101,"설정") -> -586901688 | D14: =SUMIFS(분개상세!$N$2:$N$101,분개상세!$I$2:$I$101,38160000,분개상세!$L$2:$L$101,"'26 Fit for purpose",분개상세!$M$2:$M$101,"환입")+SUMIFS(분개상세!$N$2:$N$101,분개상세!$I$2:$I$101,42910311,분개상세!$L$2:$L$101,"'26 Fit for purpose",분개상세!$M$2:$M$101,"환입") -> 586901688 | E14: =SUMIFS(분개상세!$N$2:$N$101,분개상세!$I$2:$I$101,38160000,분개상세!$L$2:$L$101,"'26 Fit for purpose",분개상세!$M$2:$M$101,"사용")+SUMIFS(분개상세!$N$2:$N$101,분개상세!$I$2:$I$101,42910311,분개상세!$L$2:$L$101,"'26 Fit for purpose",분개상세!$M$2:$M$101,"사용") -> 0 | F14: =SUMIFS(분개상세!$N$2:$N$101,분개상세!$I$2:$I$101,38160000,분개상세!$L$2:$L$101,"'26 Fit for purpose",분개상세!$M$2:$M$101,"재분류(전기전표 역분개)")+SUMIFS(분개상세!$N$2:$N$101,분개상세!$I$2:$I$101,42910311,분개상세!$L$2:$L$101,"'26 Fit for purpose",분개상세!$M$2:$M$101,"재분류(전기전표 역분개)") -> 0 | G14: =SUM(B14:F14) -> 0 | H14: 4월 설정 → 9월 전액 환입
A15: '26 Key market | B15: 0 | C15: =SUMIFS(분개상세!$N$2:$N$101,분개상세!$I$2:$I$101,38160000,분개상세!$L$2:$L$101,"'26 Key market",분개상세!$M$2:$M$101,"설정")+SUMIFS(분개상세!$N$2:$N$101,분개상세!$I$2:$I$101,42910311,분개상세!$L$2:$L$101,"'26 Key market",분개상세!$M$2:$M$101,"설정") -> -389693489 | D15: =SUMIFS(분개상세!$N$2:$N$101,분개상세!$I$2:$I$101,38160000,분개상세!$L$2:$L$101,"'26 Key market",분개상세!$M$2:$M$101,"환입")+SUMIFS(분개상세!$N$2:$N$101,분개상세!$I$2:$I$101,42910311,분개상세!$L$2:$L$101,"'26 Key market",분개상세!$M$2:$M$101,"환입") -> 0 | E15: =SUMIFS(분개상세!$N$2:$N$101,분개상세!$I$2:$I$101,38160000,분개상세!$L$2:$L$101,"'26 Key market",분개상세!$M$2:$M$101,"사용")+SUMIFS(분개상세!$N$2:$N$101,분개상세!$I$2:$I$101,42910311,분개상세!$L$2:$L$101,"'26 Key market",분개상세!$M$2:$M$101,"사용") -> 0 | F15: =SUMIFS(분개상세!$N$2:$N$101,분개상세!$I$2:$I$101,38160000,분개상세!$L$2:$L$101,"'26 Key market",분개상세!$M$2:$M$101,"재분류(전기전표 역분개)")+SUMIFS(분개상세!$N$2:$N$101,분개상세!$I$2:$I$101,42910311,분개상세!$L$2:$L$101,"'26 Key market",분개상세!$M$2:$M$101,"재분류(전기전표 역분개)") -> 0 | G15: =SUM(B15:F15) -> -389693489
A16: '26 Argos | B16: -3500000 | C16: =SUMIFS(분개상세!$N$2:$N$101,분개상세!$I$2:$I$101,38160000,분개상세!$L$2:$L$101,"'26 Argos",분개상세!$M$2:$M$101,"설정")+SUMIFS(분개상세!$N$2:$N$101,분개상세!$I$2:$I$101,42910311,분개상세!$L$2:$L$101,"'26 Argos",분개상세!$M$2:$M$101,"설정") -> -36886531 | D16: =SUMIFS(분개상세!$N$2:$N$101,분개상세!$I$2:$I$101,38160000,분개상세!$L$2:$L$101,"'26 Argos",분개상세!$M$2:$M$101,"환입")+SUMIFS(분개상세!$N$2:$N$101,분개상세!$I$2:$I$101,42910311,분개상세!$L$2:$L$101,"'26 Argos",분개상세!$M$2:$M$101,"환입") -> 3500000 | E16: =SUMIFS(분개상세!$N$2:$N$101,분개상세!$I$2:$I$101,38160000,분개상세!$L$2:$L$101,"'26 Argos",분개상세!$M$2:$M$101,"사용")+SUMIFS(분개상세!$N$2:$N$101,분개상세!$I$2:$I$101,42910311,분개상세!$L$2:$L$101,"'26 Argos",분개상세!$M$2:$M$101,"사용") -> 0 | F16: =SUMIFS(분개상세!$N$2:$N$101,분개상세!$I$2:$I$101,38160000,분개상세!$L$2:$L$101,"'26 Argos",분개상세!$M$2:$M$101,"재분류(전기전표 역분개)")+SUMIFS(분개상세!$N$2:$N$101,분개상세!$I$2:$I$101,42910311,분개상세!$L$2:$L$101,"'26 Argos",분개상세!$M$2:$M$101,"재분류(전기전표 역분개)") -> 0 | G16: =SUM(B16:F16) -> -36886531 | H16: 전직지원 4월 환입(전기 설정분), VRP 4월 추가설정
A17: '26 Procurement transformation | B17: 0 | C17: =SUMIFS(분개상세!$N$2:$N$101,분개상세!$I$2:$I$101,38160000,분개상세!$L$2:$L$101,"'26 Procurement transformation",분개상세!$M$2:$M$101,"설정")+SUMIFS(분개상세!$N$2:$N$101,분개상세!$I$2:$I$101,42910311,분개상세!$L$2:$L$101,"'26 Procurement transformation",분개상세!$M$2:$M$101,"설정") -> -294313854 | D17: =SUMIFS(분개상세!$N$2:$N$101,분개상세!$I$2:$I$101,38160000,분개상세!$L$2:$L$101,"'26 Procurement transformation",분개상세!$M$2:$M$101,"환입")+SUMIFS(분개상세!$N$2:$N$101,분개상세!$I$2:$I$101,42910311,분개상세!$L$2:$L$101,"'26 Procurement transformation",분개상세!$M$2:$M$101,"환입") -> 0 | E17: =SUMIFS(분개상세!$N$2:$N$101,분개상세!$I$2:$I$101,38160000,분개상세!$L$2:$L$101,"'26 Procurement transformation",분개상세!$M$2:$M$101,"사용")+SUMIFS(분개상세!$N$2:$N$101,분개상세!$I$2:$I$101,42910311,분개상세!$L$2:$L$101,"'26 Procurement transformation",분개상세!$M$2:$M$101,"사용") -> 0 | F17: =SUMIFS(분개상세!$N$2:$N$101,분개상세!$I$2:$I$101,38160000,분개상세!$L$2:$L$101,"'26 Procurement transformation",분개상세!$M$2:$M$101,"재분류(전기전표 역분개)")+SUMIFS(분개상세!$N$2:$N$101,분개상세!$I$2:$I$101,42910311,분개상세!$L$2:$L$101,"'26 Procurement transformation",분개상세!$M$2:$M$101,"재분류(전기전표 역분개)") -> 0 | G17: =SUM(B17:F17) -> -294313854
A18: '26 DD&O Footprint | B18: 0 | C18: =SUMIFS(분개상세!$N$2:$N$101,분개상세!$I$2:$I$101,38160000,분개상세!$L$2:$L$101,"'26 DD&O Footprint",분개상세!$M$2:$M$101,"설정")+SUMIFS(분개상세!$N$2:$N$101,분개상세!$I$2:$I$101,42910311,분개상세!$L$2:$L$101,"'26 DD&O Footprint",분개상세!$M$2:$M$101,"설정") -> -249144072 | D18: =SUMIFS(분개상세!$N$2:$N$101,분개상세!$I$2:$I$101,38160000,분개상세!$L$2:$L$101,"'26 DD&O Footprint",분개상세!$M$2:$M$101,"환입")+SUMIFS(분개상세!$N$2:$N$101,분개상세!$I$2:$I$101,42910311,분개상세!$L$2:$L$101,"'26 DD&O Footprint",분개상세!$M$2:$M$101,"환입") -> 0 | E18: =SUMIFS(분개상세!$N$2:$N$101,분개상세!$I$2:$I$101,38160000,분개상세!$L$2:$L$101,"'26 DD&O Footprint",분개상세!$M$2:$M$101,"사용")+SUMIFS(분개상세!$N$2:$N$101,분개상세!$I$2:$I$101,42910311,분개상세!$L$2:$L$101,"'26 DD&O Footprint",분개상세!$M$2:$M$101,"사용") -> 0 | F18: =SUMIFS(분개상세!$N$2:$N$101,분개상세!$I$2:$I$101,38160000,분개상세!$L$2:$L$101,"'26 DD&O Footprint",분개상세!$M$2:$M$101,"재분류(전기전표 역분개)")+SUMIFS(분개상세!$N$2:$N$101,분개상세!$I$2:$I$101,42910311,분개상세!$L$2:$L$101,"'26 DD&O Footprint",분개상세!$M$2:$M$101,"재분류(전기전표 역분개)") -> 0 | G18: =SUM(B18:F18) -> -249144072
A19: 기초 재분류 | B19: 0 | C19: =SUMIFS(분개상세!$N$2:$N$101,분개상세!$I$2:$I$101,38160000,분개상세!$L$2:$L$101,"기초 재분류",분개상세!$M$2:$M$101,"설정")+SUMIFS(분개상세!$N$2:$N$101,분개상세!$I$2:$I$101,42910311,분개상세!$L$2:$L$101,"기초 재분류",분개상세!$M$2:$M$101,"설정") -> 0 | D19: =SUMIFS(분개상세!$N$2:$N$101,분개상세!$I$2:$I$101,38160000,분개상세!$L$2:$L$101,"기초 재분류",분개상세!$M$2:$M$101,"환입")+SUMIFS(분개상세!$N$2:$N$101,분개상세!$I$2:$I$101,42910311,분개상세!$L$2:$L$101,"기초 재분류",분개상세!$M$2:$M$101,"환입") -> 0 | E19: =SUMIFS(분개상세!$N$2:$N$101,분개상세!$I$2:$I$101,38160000,분개상세!$L$2:$L$101,"기초 재분류",분개상세!$M$2:$M$101,"사용")+SUMIFS(분개상세!$N$2:$N$101,분개상세!$I$2:$I$101,42910311,분개상세!$L$2:$L$101,"기초 재분류",분개상세!$M$2:$M$101,"사용") -> 0 | F19: =SUMIFS(분개상세!$N$2:$N$101,분개상세!$I$2:$I$101,38160000,분개상세!$L$2:$L$101,"기초 재분류",분개상세!$M$2:$M$101,"재분류(전기전표 역분개)")+SUMIFS(분개상세!$N$2:$N$101,분개상세!$I$2:$I$101,42910311,분개상세!$L$2:$L$101,"기초 재분류",분개상세!$M$2:$M$101,"재분류(전기전표 역분개)") -> 0 | G19: =SUM(B19:F19) -> 0 | H19: 1/1 전기전표(10016118) 역분개, 계정 내 순액 0
A20: 합계 | B20: =SUM(B12:B19) -> -16996071611 | C20: =SUM(C12:C19) -> -1556939634 | D20: =SUM(D12:D19) -> 2938753560 | E20: =SUM(E12:E19) -> 11099073298 | F20: =SUM(F12:F19) -> 0 | G20: =SUM(G12:G19) -> -4515184387
A21: BSPL 9월말 (38160000+42910311) | G21: -4515184387
A22: 차이 | G22: =G20-G21 -> 0
A24: 3. 손익 영향 (70051000 전입/환입, 판관비-급여)
A25: 프로그램 | B25: VRP 설정 | C25: VRP 환입 | D25: 전직지원 설정 | E25: 전직지원 환입 | F25: 합계 | G25: 비고
A26: '25 Drive 2 (commercial) | B26: =SUMIFS(분개상세!$N$2:$N$101,분개상세!$I$2:$I$101,70051000,분개상세!$L$2:$L$101,"'25 Drive 2 (commercial)",분개상세!$M$2:$M$101,"설정",분개상세!$K$2:$K$101,"<>*outplacement*") -> 0 | C26: =SUMIFS(분개상세!$N$2:$N$101,분개상세!$I$2:$I$101,70051000,분개상세!$L$2:$L$101,"'25 Drive 2 (commercial)",분개상세!$M$2:$M$101,"환입",분개상세!$K$2:$K$101,"<>*outplacement*") -> -2271351872 | D26: =SUMIFS(분개상세!$N$2:$N$101,분개상세!$I$2:$I$101,70051000,분개상세!$L$2:$L$101,"'25 Drive 2 (commercial)",분개상세!$M$2:$M$101,"설정",분개상세!$K$2:$K$101,"*outplacement*") -> 0 | E26: =SUMIFS(분개상세!$N$2:$N$101,분개상세!$I$2:$I$101,70051000,분개상세!$L$2:$L$101,"'25 Drive 2 (commercial)",분개상세!$M$2:$M$101,"환입",분개상세!$K$2:$K$101,"*outplacement*") -> -66500000 | F26: =SUM(B26:E26) -> -2337851872
A27: '26 Fit for purpose | B27: =SUMIFS(분개상세!$N$2:$N$101,분개상세!$I$2:$I$101,70051000,분개상세!$L$2:$L$101,"'26 Fit for purpose",분개상세!$M$2:$M$101,"설정",분개상세!$K$2:$K$101,"<>*outplacement*") -> 583401688 | C27: =SUMIFS(분개상세!$N$2:$N$101,분개상세!$I$2:$I$101,70051000,분개상세!$L$2:$L$101,"'26 Fit for purpose",분개상세!$M$2:$M$101,"환입",분개상세!$K$2:$K$101,"<>*outplacement*") -> -583401688 | D27: =SUMIFS(분개상세!$N$2:$N$101,분개상세!$I$2:$I$101,70051000,분개상세!$L$2:$L$101,"'26 Fit for purpose",분개상세!$M$2:$M$101,"설정",분개상세!$K$2:$K$101,"*outplacement*") -> 3500000 | E27: =SUMIFS(분개상세!$N$2:$N$101,분개상세!$I$2:$I$101,70051000,분개상세!$L$2:$L$101,"'26 Fit for purpose",분개상세!$M$2:$M$101,"환입",분개상세!$K$2:$K$101,"*outplacement*") -> -3500000 | F27: =SUM(B27:E27) -> 0
A28: '26 Key market | B28: =SUMIFS(분개상세!$N$2:$N$101,분개상세!$I$2:$I$101,70051000,분개상세!$L$2:$L$101,"'26 Key market",분개상세!$M$2:$M$101,"설정",분개상세!$K$2:$K$101,"<>*outplacement*") -> 386193489 | C28: =SUMIFS(분개상세!$N$2:$N$101,분개상세!$I$2:$I$101,70051000,분개상세!$L$2:$L$101,"'26 Key market",분개상세!$M$2:$M$101,"환입",분개상세!$K$2:$K$101,"<>*outplacement*") -> 0 | D28: =SUMIFS(분개상세!$N$2:$N$101,분개상세!$I$2:$I$101,70051000,분개상세!$L$2:$L$101,"'26 Key market",분개상세!$M$2:$M$101,"설정",분개상세!$K$2:$K$101,"*outplacement*") -> 3500000 | E28: =SUMIFS(분개상세!$N$2:$N$101,분개상세!$I$2:$I$101,70051000,분개상세!$L$2:$L$101,"'26 Key market",분개상세!$M$2:$M$101,"환입",분개상세!$K$2:$K$101,"*outplacement*") -> 0 | F28: =SUM(B28:E28) -> 389693489
A29: '26 Argos | B29: =SUMIFS(분개상세!$N$2:$N$101,분개상세!$I$2:$I$101,70051000,분개상세!$L$2:$L$101,"'26 Argos",분개상세!$M$2:$M$101,"설정",분개상세!$K$2:$K$101,"<>*outplacement*") -> 36886531 | C29: =SUMIFS(분개상세!$N$2:$N$101,분개상세!$I$2:$I$101,70051000,분개상세!$L$2:$L$101,"'26 Argos",분개상세!$M$2:$M$101,"환입",분개상세!$K$2:$K$101,"<>*outplacement*") -> 0 | D29: =SUMIFS(분개상세!$N$2:$N$101,분개상세!$I$2:$I$101,70051000,분개상세!$L$2:$L$101,"'26 Argos",분개상세!$M$2:$M$101,"설정",분개상세!$K$2:$K$101,"*outplacement*") -> 0 | E29: =SUMIFS(분개상세!$N$2:$N$101,분개상세!$I$2:$I$101,70051000,분개상세!$L$2:$L$101,"'26 Argos",분개상세!$M$2:$M$101,"환입",분개상세!$K$2:$K$101,"*outplacement*") -> -3500000 | F29: =SUM(B29:E29) -> 33386531
A30: '26 Procurement transformation | B30: =SUMIFS(분개상세!$N$2:$N$101,분개상세!$I$2:$I$101,70051000,분개상세!$L$2:$L$101,"'26 Procurement transformation",분개상세!$M$2:$M$101,"설정",분개상세!$K$2:$K$101,"<>*outplacement*") -> 290813854 | C30: =SUMIFS(분개상세!$N$2:$N$101,분개상세!$I$2:$I$101,70051000,분개상세!$L$2:$L$101,"'26 Procurement transformation",분개상세!$M$2:$M$101,"환입",분개상세!$K$2:$K$101,"<>*outplacement*") -> 0 | D30: =SUMIFS(분개상세!$N$2:$N$101,분개상세!$I$2:$I$101,70051000,분개상세!$L$2:$L$101,"'26 Procurement transformation",분개상세!$M$2:$M$101,"설정",분개상세!$K$2:$K$101,"*outplacement*") -> 3500000 | E30: =SUMIFS(분개상세!$N$2:$N$101,분개상세!$I$2:$I$101,70051000,분개상세!$L$2:$L$101,"'26 Procurement transformation",분개상세!$M$2:$M$101,"환입",분개상세!$K$2:$K$101,"*outplacement*") -> 0 | F30: =SUM(B30:E30) -> 294313854
A31: '26 DD&O Footprint | B31: =SUMIFS(분개상세!$N$2:$N$101,분개상세!$I$2:$I$101,70051000,분개상세!$L$2:$L$101,"'26 DD&O Footprint",분개상세!$M$2:$M$101,"설정",분개상세!$K$2:$K$101,"<>*outplacement*") -> 245644072 | C31: =SUMIFS(분개상세!$N$2:$N$101,분개상세!$I$2:$I$101,70051000,분개상세!$L$2:$L$101,"'26 DD&O Footprint",분개상세!$M$2:$M$101,"환입",분개상세!$K$2:$K$101,"<>*outplacement*") -> 0 | D31: =SUMIFS(분개상세!$N$2:$N$101,분개상세!$I$2:$I$101,70051000,분개상세!$L$2:$L$101,"'26 DD&O Footprint",분개상세!$M$2:$M$101,"설정",분개상세!$K$2:$K$101,"*outplacement*") -> 3500000 | E31: =SUMIFS(분개상세!$N$2:$N$101,분개상세!$I$2:$I$101,70051000,분개상세!$L$2:$L$101,"'26 DD&O Footprint",분개상세!$M$2:$M$101,"환입",분개상세!$K$2:$K$101,"*outplacement*") -> 0 | F31: =SUM(B31:E31) -> 249144072
A32: 합계 | B32: =SUM(B26:B31) -> 1542939634 | C32: =SUM(C26:C31) -> -2854753560 | D32: =SUM(D26:D31) -> 14000000 | E32: =SUM(E26:E31) -> -73500000 | F32: =SUM(F26:F31) -> -1371313926
A33: 70051000 GL 합계 / BSPL 9월 | B33: =SUMIFS(분개상세!$N$2:$N$101,분개상세!$I$2:$I$101,70051000) -> -1371313926 | F33: -1371313926
A34: 차이 | F34: =B33-F33 -> 0
A36: 4. '25 Drive 2 VRP 사용액 vs 실제 지급(62100747 경유)
A37: 월 | B37: 충당부채 사용(38160000 차변) | C37: 실제 지급(62100747) | D37: 차이 | E37: 비고
A38: 1월 | B38: =SUMIFS(분개상세!$N$2:$N$101,분개상세!$I$2:$I$101,38160000,분개상세!$M$2:$M$101,"사용",분개상세!$B$2:$B$101,1) -> 9029878628 | C38: =SUMIFS('VRP 지급내역'!$H$2:$H$19,'VRP 지급내역'!$B$2:$B$19,1) -> 9026382321 | D38: =B38-C38 -> 3496307 | E38: 급여대장 5,290.8백만 + 연금사업자 3,735.6백만
A39: 2월 | B39: =SUMIFS(분개상세!$N$2:$N$101,분개상세!$I$2:$I$101,38160000,분개상세!$M$2:$M$101,"사용",분개상세!$B$2:$B$101,2) -> 763810731 | C39: =SUMIFS('VRP 지급내역'!$H$2:$H$19,'VRP 지급내역'!$B$2:$B$19,2) -> 773240036 | D39: =B39-C39 -> -9429305 | E39: 급여대장 773.2백만 / 사용 773.2백만, 1월 과다사용 조정 -9.4백만 포함
A40: 4월 | B40: =SUMIFS(분개상세!$N$2:$N$101,분개상세!$I$2:$I$101,38160000,분개상세!$M$2:$M$101,"사용",분개상세!$B$2:$B$101,4) -> 552383939 | C40: =SUMIFS('VRP 지급내역'!$H$2:$H$19,'VRP 지급내역'!$B$2:$B$19,4) -> 554771272 | D40: =B40-C40 -> -2387333 | E40: 연금사업자 554.8백만 (중복기표 1건 역분개)
A41: 7월 | B41: =SUMIFS(분개상세!$N$2:$N$101,분개상세!$I$2:$I$101,38160000,분개상세!$M$2:$M$101,"사용",분개상세!$B$2:$B$101,7) -> 742500000 | C41: =SUMIFS('VRP 지급내역'!$H$2:$H$19,'VRP 지급내역'!$B$2:$B$19,7) -> 742500000 | D41: =B41-C41 -> 0 | E41: 급여대장 742.5백만
A42: 합계 | B42: =SUM(B38:B41) -> 11088573298 | C42: =SUM(C38:C41) -> 11096893629 | D42: =SUM(D38:D41) -> -8320331
A44: 5. GL 확인 결과 및 검토 포인트
A45: ① 38160000 9월말 잔액 4,473,184,387원 = '25 Drive 2 잔액 3,513,650,452원 + '26 신규 4건 959,533,935원(Key market 386.2 / Argos 36.9 / Procurement 290.8 / DD&O 245.6백만원). BSPL과 일치.
...

Sheet 분개상세
A1: 전표번호 | B1: 기간 | C1: 전기일 | D1: 증빙일 | E1: 전표유형 | F1: 입력자 | G1: 헤더텍스트 | H1: 역분개전표 | I1: G/L | J1: 계정명 | K1: 적요 | L1: 프로그램 | M1: 구분 | N1: 금액(원, 차변+)
A2: 10000143 | B2: 1 | C2: 46023 | D2: 46022 | E2: AB | F2: U1096412 | H2: 10016118 | I2: 38160000 | J2: 구조조정충당부채-VRP (미지급비용) | L2: 기초 재분류 | M2: 재분류(전기전표 역분개) | N2: 1228771976
A3: 10000143 | B3: 1 | C3: 46023 | D3: 46022 | E3: AB | F3: U1096412 | H3: 10016118 | I3: 38160000 | J3: 구조조정충당부채-VRP (미지급비용) | L3: 기초 재분류 | M3: 재분류(전기전표 역분개) | N3: -14455123
A4: 10000143 | B4: 1 | C4: 46023 | D4: 46022 | E4: AB | F4: U1096412 | H4: 10016118 | I4: 38160000 | J4: 구조조정충당부채-VRP (미지급비용) | L4: 기초 재분류 | M4: 재분류(전기전표 역분개) | N4: -954316853
A5: 10000143 | B5: 1 | C5: 46023 | D5: 46022 | E5: AB | F5: U1096412 | H5: 10016118 | I5: 38160000 | J5: 구조조정충당부채-VRP (미지급비용) | L5: 기초 재분류 | M5: 재분류(전기전표 역분개) | N5: -260000000
A6: 120000018 | B6: 1 | C6: 46053 | D6: 46053 | E6: SB | F6: U1096412 | G6: Provision '25_Drive 2 VRP | I6: 38160000 | J6: 구조조정충당부채-VRP (미지급비용) | K6: Prov.'25_Drive 2 VRP_commercial | L6: '25 Drive 2 (commercial) | M6: 사용 | N6: 139366409
A7: 120000018 | B7: 1 | C7: 46053 | D7: 46053 | E7: SB | F7: U1096412 | G7: Provision '25_Drive 2 VRP | I7: 38160000 | J7: 구조조정충당부채-VRP (미지급비용) | K7: Prov.'25_Drive 2 VRP_commercial | L7: '25 Drive 2 (commercial) | M7: 사용 | N7: 194499104
A8: 120000018 | B8: 1 | C8: 46053 | D8: 46053 | E8: SB | F8: U1096412 | G8: Provision '25_Drive 2 VRP | I8: 38160000 | J8: 구조조정충당부채-VRP (미지급비용) | K8: Prov.'25_Drive 2 VRP_commercial | L8: '25 Drive 2 (commercial) | M8: 사용 | N8: 1314748766
A9: 120000018 | B9: 1 | C9: 46053 | D9: 46053 | E9: SB | F9: U1096412 | G9: Provision '25_Drive 2 VRP | I9: 38160000 | J9: 구조조정충당부채-VRP (미지급비용) | K9: Prov.'25_Drive 2 VRP_commercial | L9: '25 Drive 2 (commercial) | M9: 사용 | N9: 732377864
A10: 120000018 | B10: 1 | C10: 46053 | D10: 46053 | E10: SB | F10: U1096412 | G10: Provision '25_Drive 2 VRP | I10: 38160000 | J10: 구조조정충당부채-VRP (미지급비용) | K10: Prov.'25_Drive 2 VRP_commercial | L10: '25 Drive 2 (commercial) | M10: 사용 | N10: 292240228
A11: 120000018 | B11: 1 | C11: 46053 | D11: 46053 | E11: SB | F11: U1096412 | G11: Provision '25_Drive 2 VRP | I11: 38160000 | J11: 구조조정충당부채-VRP (미지급비용) | K11: Prov.'25_Drive 2 VRP_commercial | L11: '25 Drive 2 (commercial) | M11: 사용 | N11: 637997113
A12: 120000018 | B12: 1 | C12: 46053 | D12: 46053 | E12: SB | F12: U1096412 | G12: Provision '25_Drive 2 VRP | I12: 38160000 | J12: 구조조정충당부채-VRP (미지급비용) | K12: Prov.'25_Drive 2 VRP_commercial | L12: '25 Drive 2 (commercial) | M12: 사용 | N12: 1595518809
A13: 120000018 | B13: 1 | C13: 46053 | D13: 46053 | E13: SB | F13: U1096412 | G13: Provision '25_Drive 2 VRP | I13: 38160000 | J13: 구조조정충당부채-VRP (미지급비용) | K13: Prov.'25_Drive 2 VRP_commercial | L13: '25 Drive 2 (commercial) | M13: 사용 | N13: 2521212015
A14: 120000018 | B14: 1 | C14: 46053 | D14: 46053 | E14: SB | F14: U1096412 | G14: Provision '25_Drive 2 VRP | I14: 38160000 | J14: 구조조정충당부채-VRP (미지급비용) | K14: Prov.'25_Drive 2 VRP_commercial | L14: '25 Drive 2 (commercial) | M14: 사용 | N14: 201128684
A15: 120000018 | B15: 1 | C15: 46053 | D15: 46053 | E15: SB | F15: U1096412 | G15: Provision '25_Drive 2 VRP | I15: 38160000 | J15: 구조조정충당부채-VRP (미지급비용) | K15: Prov.'25_Drive 2 VRP_commercial | L15: '25 Drive 2 (commercial) | M15: 사용 | N15: 768016582
A16: 120000018 | B16: 1 | C16: 46053 | D16: 46053 | E16: SB | F16: U1096412 | G16: Provision '25_Drive 2 VRP | I16: 38160000 | J16: 구조조정충당부채-VRP (미지급비용) | K16: Prov.'25_Drive 2 VRP_commercial | L16: '25 Drive 2 (commercial) | M16: 사용 | N16: 632773054
A17: 120000018 | B17: 1 | C17: 46053 | D17: 46053 | E17: SB | F17: U1096412 | G17: Provision '25_Drive 2 VRP | I17: 62100747 | J17: 퇴직급여-DC (VRP 지급 경유) | K17: Prov.'25_Drive 2 VRP_commercial | L17: '25 Drive 2 (commercial) | M17: 사용 | N17: -139366409
... A49: 120000055 | B49: 2 | C49: 46081 | D49: 46081 | E49: SB | F49: U1096412 | G49: Provision '25_Drive 2 VRP | I49: 62100747 | J49: 퇴직급여-DC (VRP 지급 경유) | K49: Prov.'25_Drive 2 VRP_commercial_adj | L49: '25 Drive 2 (commercial) | M49: 사용 | N49: -773240036
A50: 120000070 | B50: 3 | C50: 46112 | D50: 46112 | E50: SB | F50: U1096412 | G50: Provision Pharma Restruct | H50: 120000071 | I50: 38160000 | J50: 구조조정충당부채-VRP (미지급비용) | K50: Prov.'25_Drive 2 VRP_commercial_adj | L50: '25 Drive 2 (commercial) | M50: 기표 후 역분개 | N50: 2271351872
A51: 120000070 | B51: 3 | C51: 46112 | D51: 46112 | E51: SB | F51: U1096412 | G51: Provision Pharma Restruct | H51: 120000071 | I51: 42910311 | J51: 구조조정충당부채-전직지원 (미지급비용) | K51: Prov.'25_Drive 2 outplacement_commercial_adj | L51: '25 Drive 2 (commercial) | M51: 기표 후 역분개 | N51: 80500000
A52: 120000070 | B52: 3 | C52: 46112 | D52: 46112 | E52: SB | F52: U1096412 | G52: Provision Pharma Restruct | H52: 120000071 | I52: 70051000 | J52: 구조조정충당부채 전입/환입 (판관비-급여) | K52: Prov.'25_Drive 2 VRP_commercial_adj | L52: '25 Drive 2 (commercial) | M52: 기표 후 역분개 | N52: -2271351872
A53: 120000070 | B53: 3 | C53: 46112 | D53: 46112 | E53: SB | F53: U1096412 | G53: Provision Pharma Restruct | H53: 120000071 | I53: 70051000 | J53: 구조조정충당부채 전입/환입 (판관비-급여) | K53: Prov.'25_Drive 2 outplacement_commercial_adj | L53: '25 Drive 2 (commercial) | M53: 기표 후 역분개 | N53: -80500000
A54: 120000071 | B54: 3 | C54: 46112 | D54: 46112 | E54: SB | F54: BL_JE_WS | G54: Provision Pharma Restruct | H54: 120000070 | I54: 38160000 | J54: 구조조정충당부채-VRP (미지급비용) | K54: Prov.'25_Drive 2 VRP_commercial_adj | L54: '25 Drive 2 (commercial) | M54: 기표 후 역분개 | N54: -2271351872
A55: 120000071 | B55: 3 | C55: 46112 | D55: 46112 | E55: SB | F55: BL_JE_WS | G55: Provision Pharma Restruct | H55: 120000070 | I55: 42910311 | J55: 구조조정충당부채-전직지원 (미지급비용) | K55: Prov.'25_Drive 2 outplacement_commercial_adj | L55: '25 Drive 2 (commercial) | M55: 기표 후 역분개 | N55: -80500000
A56: 120000071 | B56: 3 | C56: 46112 | D56: 46112 | E56: SB | F56: BL_JE_WS | G56: Provision Pharma Restruct | H56: 120000070 | I56: 70051000 | J56: 구조조정충당부채 전입/환입 (판관비-급여) | K56: Prov.'25_Drive 2 VRP_commercial_adj | L56: '25 Drive 2 (commercial) | M56: 기표 후 역분개 | N56: 2271351872
A57: 120000071 | B57: 3 | C57: 46112 | D57: 46112 | E57: SB | F57: BL_JE_WS | G57: Provision Pharma Restruct | H57: 120000070 | I57: 70051000 | J57: 구조조정충당부채 전입/환입 (판관비-급여) | K57: Prov.'25_Drive 2 outplacement_commercial_adj | L57: '25 Drive 2 (commercial) | M57: 기표 후 역분개 | N57: 80500000
A58: 120000074 | B58: 3 | C58: 46112 | D58: 46112 | E58: SB | F58: U1096412 | G58: Provision '25_Drive 2 VRP | I58: 38160000 | J58: 구조조정충당부채-VRP (미지급비용) | K58: Prov.'25_Drive 2 VRP_commercial_adj | L58: '25 Drive 2 (commercial) | M58: 환입 | N58: 2271351872
A59: 120000074 | B59: 3 | C59: 46112 | D59: 46112 | E59: SB | F59: U1096412 | G59: Provision '25_Drive 2 VRP | I59: 42910311 | J59: 구조조정충당부채-전직지원 (미지급비용) | K59: Prov.'25_Drive 2 outplacement_commercial_adj | L59: '25 Drive 2 (commercial) | M59: 환입 | N59: 10500000
A60: 120000074 | B60: 3 | C60: 46112 | D60: 46112 | E60: SB | F60: U1096412 | G60: Provision '25_Drive 2 VRP | I60: 42910311 | J60: 구조조정충당부채-전직지원 (미지급비용) | K60: Prov.'24_Drive_noncommercial_reclass | L60: '24 Drive | M60: 사용 | N60: 3500000
A61: 120000074 | B61: 3 | C61: 46112 | D61: 46112 | E61: SB | F61: U1096412 | G61: Provision '25_Drive 2 VRP | I61: 68063200 | J61: 지급수수료-Outplacement | K61: Prov.'24_Drive_noncommercial_reclass | L61: '24 Drive | M61: 사용 | N61: -3500000
A62: 120000074 | B62: 3 | C62: 46112 | D62: 46112 | E62: SB | F62: U1096412 | G62: Provision '25_Drive 2 VRP | I62: 70051000 | J62: 구조조정충당부채 전입/환입 (판관비-급여) | K62: Prov.'25_Drive 2 VRP_commercial_adj | L62: '25 Drive 2 (commercial) | M62: 환입 | N62: -2271351872
A63: 120000074 | B63: 3 | C63: 46112 | D63: 46112 | E63: SB | F63: U1096412 | G63: Provision '25_Drive 2 VRP | I63: 70051000 | J63: 구조조정충당부채 전입/환입 (판관비-급여) | K63: Prov.'25_Drive 2 outplacement_commercial_adj | L63: '25 Drive 2 (commercial) | M63: 환입 | N63: -10500000
A64: 120000092 | B64: 4 | C64: 46142 | D64: 46142 | E64: SB | F64: U1096412 | G64: Provision '26 | I64: 38160000 | J64: 구조조정충당부채-VRP (미지급비용) | K64: Prov.'26_fit for purpose VRP_noncommercial | L64: '26 Fit for purpose | M64: 설정 | N64: -583401688
A65: 120000092 | B65: 4 | C65: 46142 | D65: 46142 | E65: SB | F65: U1096412 | G65: Provision '26 | I65: 38160000 | J65: 구조조정충당부채-VRP (미지급비용) | K65: Prov.'26_key market VRP_noncommercial | L65: '26 Key market | M65: 설정 | N65: -386193489
A66: 120000092 | B66: 4 | C66: 46142 | D66: 46142 | E66: SB | F66: U1096412 | G66: Provision '26 | I66: 38160000 | J66: 구조조정충당부채-VRP (미지급비용) | K66: Prov.'26_Argos add'l VRP_noncommercial | L66: '26 Argos | M66: 설정 | N66: -36886531
A67: 120000092 | B67: 4 | C67: 46142 | D67: 46142 | E67: SB | F67: U1096412 | G67: Provision '26 | I67: 42910311 | J67: 구조조정충당부채-전직지원 (미지급비용) | K67: Prov.'26_fit for purpose outplacement_noncommercia | L67: '26 Fit for purpose | M67: 설정 | N67: -3500000
A68: 120000092 | B68: 4 | C68: 46142 | D68: 46142 | E68: SB | F68: U1096412 | G68: Provision '26 | I68: 42910311 | J68: 구조조정충당부채-전직지원 (미지급비용) | K68: Prov.'26_key market outplacement_noncommercial | L68: '26 Key market | M68: 설정 | N68: -3500000
A69: 120000092 | B69: 4 | C69: 46142 | D69: 46142 | E69: SB | F69: U1096412 | G69: Provision '26 | I69: 42910311 | J69: 구조조정충당부채-전직지원 (미지급비용) | K69: Prov.'26_Argos outplacement reversal_noncommercial | L69: '26 Argos | M69: 환입 | N69: 3500000
... A101: 120000190 | B101: 9 | C101: 46295 | D101: 46295 | E101: SB | F101: U1096412 | G101: VRP PROVISION'26 | I101: 70051000 | J101: 구조조정충당부채 전입/환입 (판관비-급여) | K101: Outplacement '25_Drive 25 2_commercial_reversal | L101: '25 Drive 2 (commercial) | M101: 환입 | N101: -3500000

Sheet VRP 지급내역
A1: 전표번호 | B1: 기간 | C1: 전기일 | D1: 전표유형 | E1: 헤더텍스트 | F1: 적요 | G1: 상대계정 | H1: 금액(원)
A2: 190565614 | B2: 1 | C2: 46031 | D2: KR | E2: 2026년 01월 퇴직연금 | F2: 퇴직충당금 사용주부담금 | G2: 40000012 | H2: 669656093
A3: 190565615 | B3: 1 | C3: 46031 | D3: KR | E3: 2026년 01월 퇴직연금 | F3: 퇴직충당금 사용주부담금 | G3: 40000012 | H3: 201128684
A4: 190565615 | B4: 1 | C4: 46031 | D4: KR | E4: 2026년 01월 퇴직연금 | F4: 퇴직충당금 사용주부담금 | G4: 40000012 | H4: 1355026284
A5: 190565615 | B5: 1 | C5: 46031 | D5: KR | E5: 2026년 01월 퇴직연금 | F5: 퇴직충당금 사용주부담금 | G5: 40000012 | H5: 139366409
A6: 190565615 | B6: 1 | C6: 46031 | D6: KR | E6: 2026년 01월 퇴직연금 | F6: 퇴직충당금 사용주부담금 | G6: 40000012 | H6: 732377864
A7: 190565615 | B7: 1 | C7: 46031 | D7: KR | E7: 2026년 01월 퇴직연금 | F7: 퇴직충당금 사용주부담금 | G7: 40000012 | H7: 637997113
A8: 830000001 | B8: 1 | C8: 46034 | D8: SE | E8: Payroll Journal 202601 | F8: Pension DC costs-Defined contribution pl | G8: 42400000 | H8: 194099242
A9: 830000001 | B9: 1 | C9: 46034 | D9: SE | E9: Payroll Journal 202601 | F9: Pension DC costs-Defined contribution pl | G9: 42400000 | H9: 1313212538
A10: 830000001 | B10: 1 | C10: 46034 | D10: SE | E10: Payroll Journal 202601 | F10: Pension DC costs-Defined contribution pl | G10: 42400000 | H10: 292240228
A11: 830000001 | B11: 1 | C11: 46034 | D11: SE | E11: Payroll Journal 202601 | F11: Pension DC costs-Defined contribution pl | G11: 42400000 | H11: 240492525
A12: 830000001 | B12: 1 | C12: 46034 | D12: SE | E12: Payroll Journal 202601 | F12: Pension DC costs-Defined contribution pl | G12: 42400000 | H12: 1851555922
A13: 830000001 | B13: 1 | C13: 46034 | D13: SE | E13: Payroll Journal 202601 | F13: Pension DC costs-Defined contribution pl | G13: 42400000 | H13: 767113411
... A19: 830000157 | B19: 7 | C19: 46212 | D19: SE | E19: Payroll Journal 202607_of | F19: Pension DC costs-Defined contribution pl | G19: 26000810,42400000,66900000 | H19: 742500000
F21: 합계 | H21: =SUM(H2:H19) -> 11096893629
A23: 주) 연금사업자 KR 전표(퇴직충당금 사용주부담금) 중 1억원 초과 라인과 급여대장(SE) VRP 라인만 집계. 4월 190566871은 170018570으로 역분개(중복). 3월 42.6백만원(190566480), 7월 34.0백만원(190567822) 대형 라인은 VRP 여부 불명확하여 제외.
