Workbook

Sheet BS_KO
C2: 대차대조표
C4: 제 37(당) 기 2026년 12월 31일 현재 | H4: OM | I4: 0.01 | J4: ='P&L_KO'!K4 -> 7.0976202e+09
C5: 제 36(전) 기 2025년 12월 31일 현재 | H5: PM | I5: 0.8 | J5: =J4*70% -> 4.9683342e+09
H6: CTT | I6: 0.03 | J6: =J4*3% -> 2.1292861e+08
C7: 주식회사 사노피-아벤티스코리아
C8: 과목 | E8: 2026.09 | G8: 2025.12 | N8: 회사 F/S 대사 (BS_DEC 2026)
E9: 수정전 | F9: 수정후 | G9: 금액 | H9: Var. | I9: Var. % | J9: 증감분석여부? | K9: 증감분석 | N9: 회사 SAP(E열) | O9: Diff (E-N) | P9: 회사 Statutory(K열) | Q9: Diff (F-P)
C10: 자 산
B11: I. Current assets. | C11: I. 유동자산 | E11: =+E12+E27 -> 465905895178 | F11: =+F12+F27 -> 453490085054 | G11: =+G12+G27 -> 399003823525 | H11: =+H12+H27 -> 54486261529 | I11: =IFERROR(H11/G11,IF(H11>0,100%,IF(H11=0,0,-100%))) -> 0.13655574 | L11: =E11-F11 -> 12415810124 | N11: =+N12+N27 -> 465905895178 | O11: =E11-N11 -> 0 | P11: =+P12+P27 -> 453490085054 | Q11: =F11-P11 -> 0
B12: (1) Current assets. | C12: (1) 당좌자산 | E12: =SUM(E13:E24) -> 270465932072 | F12: =SUM(F13:F24) -> 258050121948 | G12: =SUM(G13:G24) -> 222568030855 | H12: =SUM(H13:H24) -> 35482091093 | I12: =IFERROR(H12/G12,IF(H12>0,100%,IF(H12=0,0,-100%))) -> 0.15942133 | L12: =E12-F12 -> 12415810124 | N12: =SUM(N13:N24) -> 270465932072 | O12: =E12-N12 -> 0 | P12: =SUM(P13:P24) -> 258050121948 | Q12: =F12-P12 -> 0
B13: 1. Cash and cash equivalents. | C13: 1. | D13: 현금및현금등가물 | E13: =SUMIF(FS_map!$H:$H,$D13,FS_map!$M:$M) -> 8328079411 | F13: =SUMIF(FS_map!$H:$H,$D13,FS_map!$P:$P) -> 8328079411 | G13: =SUMIF(WBS_2025YE!$D:$D,$D13,WBS_2025YE!$K:$K) -> 11105202344 | H13: =F13-G13 -> -2777122933 | I13: =IFERROR(H13/G13,IF(H13>0,100%,IF(H13=0,0,-100%))) -> -0.25007405 | J13: =IF(AND(ABS(H13)>$J$5,ABS(I13)>5%),"O","") | K13: 전기말 111억원 → 당기 9월말 83억원 (−28억원, HSBC 원화예금 단일계좌) 1. 당기 배당금 520억원 지급 (SAP 3월 기표, 회사 자료상 2분기 지급) 2. 그룹 현금 최적화 정책에 따라 관계사 채무를 연중 조기 결제 ※ 회사는 기말에 관계사 채무를 대량 결제하여 기말 예금잔액을 낮게 유지하는 경향이 있으므로, 기말 잔액 및 관계사 채무 결제 시점 확인 필요 | L13: =E13-F13 -> 0 | N13: =SUMIF('BS_DEC 2026'!$D:$D,$D13,'BS_DEC 2026'!$E:$E) -> 8328079411 | O13: =E13-N13 -> 0 | P13: =SUMIF('BS_DEC 2026'!$D:$D,$D13,'BS_DEC 2026'!$K:$K) -> 8328079411 | Q13: =F13-P13 -> 0
B14: 2. Accounts receivable. | C14: 2. | D14: 매출채권 | E14: =SUMIF(FS_map!$H:$H,$D14,FS_map!$M:$M) -> 227594760909 | F14: =SUMIF(FS_map!$H:$H,$D14,FS_map!$P:$P) -> 215178950785 | G14: =SUMIF(WBS_2025YE!$D:$D,$D14,WBS_2025YE!$K:$K) -> 166754777499 | H14: =F14-G14 -> 48424173286 | I14: =IFERROR(H14/G14,IF(H14>0,100%,IF(H14=0,0,-100%))) -> 0.29039152 | J14: =IF(AND(ABS(H14)>$J$5,ABS(I14)>5%),"O","") -> O | K14: 총 매출채권(SAP) 전기말 1,739억원 → 9월말 2,276억원(+537억원), 매출에누리 미지급분 직접차감(statutory #5) 124억원(전기말 72억원) 반영 후 2,152억원 1. 증가 요인: 매출 증가(9월 누적 매출 5,323억원, 전년 동기 대비 +333억원) 및 9월 매출 증가 - 주요 거래처: 비아다빈치 152억 → 197억원, 부림약품(대구) 95억 → 134억원, 지오영 106억 → 134억원, 기타 Pharma 1,194억 → 1,281억원 2. 백신 도매 매출채권은 192억 → 102억원으로 감소: 9월부터 독감백신 성수기 주문이 시작되어 4분기 증가 예상 3. 연체채권: 신광약품 69백만원 1건(12월 회수 예정, 회사 평가 low risk). 쥴릭파마는 25년 4월 계약 종료 후 유효기간 반품에 따른 credit note 정산 진행 중 4. 매출채권 회전일수(연환산 매출 기준) 111일로 전기말 94일 대비 증가 → 기간후 회수 확인 필요 (출처: 회사 BS 분석적검토 – CI2C AR 분석) | L14: =E14-F14 -> 12415810124 | N14: =SUMIF('BS_DEC 2026'!$D:$D,$D14,'BS_DEC 2026'!$E:$E) -> 227594760909 | O14: =E14-N14 -> 0 | P14: =SUMIF('BS_DEC 2026'!$D:$D,$D14,'BS_DEC 2026'!$K:$K) -> 215178950785 | Q14: =F14-P14 -> 0
B15: 3. Provision for bad debts. | C15: 3. | D15: 대손충당금 | E15: =SUMIF(FS_map!$H:$H,$D15,FS_map!$M:$M) -> -118149382 | F15: =SUMIF(FS_map!$H:$H,$D15,FS_map!$P:$P) -> -118149382 | G15: =SUMIF(WBS_2025YE!$D:$D,$D15,WBS_2025YE!$K:$K) -> -122273991 | H15: =F15-G15 -> 4124609 | I15: =IFERROR(H15/G15,IF(H15>0,100%,IF(H15=0,0,-100%))) -> -0.033732513 | J15: =IF(AND(ABS(H15)>$J$5,ABS(I15)>5%),"O","") | K15: 클리닉 매출채권에 대한 대손충당금 118백만원(전기말 122백만원). 당기 4백만원 환입(대손상각비 음수 표시). 금액 중요하지 않음 | L15: =E15-F15 -> 0 | N15: =SUMIF('BS_DEC 2026'!$D:$D,$D15,'BS_DEC 2026'!$E:$E) -> -118149382 | O15: =E15-N15 -> 0 | P15: =SUMIF('BS_DEC 2026'!$D:$D,$D15,'BS_DEC 2026'!$K:$K) -> -118149382 | Q15: =F15-P15 -> 0
B16: 4. Unpaid money. | C16: 4. | D16: 미수금 | E16: =SUMIF(FS_map!$H:$H,$D16,FS_map!$M:$M) -> 12002662102 | F16: =SUMIF(FS_map!$H:$H,$D16,FS_map!$P:$P) -> 12002662102 | G16: =SUMIF(WBS_2025YE!$D:$D,$D16,WBS_2025YE!$K:$K) -> 19254727447 | H16: =F16-G16 -> -7252065345 | I16: =IFERROR(H16/G16,IF(H16>0,100%,IF(H16=0,0,-100%))) -> -0.37663817 | J16: =IF(AND(ABS(H16)>$J$5,ABS(I16)>5%),"O","") -> O | K16: 전기말 193억원 → 9월말 120억원 (−73억원) 1. 관계사 미수금(26050000) 167억 → 116억원(−51억원) - Sanofi SA 165억 → 114억원: 3분기 R&D(CRU) 비용 recharge 미수분 - Sanofi Winthrop Industrie 1.2억원(9월 rebilling), Sanofi Pasteur Inc 1.0억원(3분기 R&D) 2. 전기말 statutory 조정으로 인식한 CRU true-up 미수금 22.6억원(86260033)은 당기 2월 확정·기표되어 잔액 0 3. 기타: 임직원 우리사주(Action Share) 공제분 4.2억원(전기말 3.1억원) | L16: =E16-F16 -> 0 | N16: =SUMIF('BS_DEC 2026'!$D:$D,$D16,'BS_DEC 2026'!$E:$E) -> 12002662102 | O16: =E16-N16 -> 0 | P16: =SUMIF('BS_DEC 2026'!$D:$D,$D16,'BS_DEC 2026'!$K:$K) -> 12002662102 | Q16: =F16-P16 -> 0
B17: 5. Value-added tax not collected. | C17: 5. | D17: 부가가치세미수금 | E17: =SUMIF(FS_map!$H:$H,$D17,FS_map!$M:$M) -> 0 | F17: =SUMIF(FS_map!$H:$H,$D17,FS_map!$P:$P) -> 0 | G17: =SUMIF(WBS_2025YE!$D:$D,$D17,WBS_2025YE!$K:$K) -> 0 | H17: =F17-G17 -> 0 | I17: =IFERROR(H17/G17,IF(H17>0,100%,IF(H17=0,0,-100%))) -> 0 | J17: =IF(AND(ABS(H17)>$J$5,ABS(I17)>5%),"O","") | L17: =E17-F17 -> 0 | N17: =SUMIF('BS_DEC 2026'!$D:$D,$D17,'BS_DEC 2026'!$E:$E) -> 0 | O17: =E17-N17 -> 0 | P17: =SUMIF('BS_DEC 2026'!$D:$D,$D17,'BS_DEC 2026'!$K:$K) -> 0 | Q17: =F17-P17 -> 0
B18: 6. Minus profit. | C18: 6. | D18: 미수수익 | E18: =SUMIF(FS_map!$H:$H,$D18,FS_map!$M:$M) -> 981690770 | F18: =SUMIF(FS_map!$H:$H,$D18,FS_map!$P:$P) -> 981690770 | G18: =SUMIF(WBS_2025YE!$D:$D,$D18,WBS_2025YE!$K:$K) -> 979522461 | H18: =F18-G18 -> 2168309 | I18: =IFERROR(H18/G18,IF(H18>0,100%,IF(H18=0,0,-100%))) -> 0.0022136389 | J18: =IF(AND(ABS(H18)>$J$5,ABS(I18)>5%),"O","") | K18: 로열티 수익 미수분: Aprovasc(한독) 955백만원, 디트로반(동화약품) 26백만원 – 9월 누적 accrual. 전기말 로열티 미수 971백만원은 당기 수령 완료 | L18: =E18-F18 -> 0 | N18: =SUMIF('BS_DEC 2026'!$D:$D,$D18,'BS_DEC 2026'!$E:$E) -> 981690770 | O18: =E18-N18 -> 0 | P18: =SUMIF('BS_DEC 2026'!$D:$D,$D18,'BS_DEC 2026'!$K:$K) -> 981690770 | Q18: =F18-P18 -> 0
B19: 7. Advance payment. | C19: 7. | D19: 선급금 | E19: =SUMIF(FS_map!$H:$H,$D19,FS_map!$M:$M) -> 1159433436 | F19: =SUMIF(FS_map!$H:$H,$D19,FS_map!$P:$P) -> 1159433436 | G19: =SUMIF(WBS_2025YE!$D:$D,$D19,WBS_2025YE!$K:$K) -> 93970356 | H19: =F19-G19 -> 1065463080 | I19: =IFERROR(H19/G19,IF(H19>0,100%,IF(H19=0,0,-100%))) -> 11.338289 | J19: =IF(AND(ABS(H19)>$J$5,ABS(I19)>5%),"O","") | K19: 전기말 94백만원 → 9월말 1,159백만원 1. 임직원 선급(Payroll deductions) 810백만원: 급여시스템 오류로 인한 일회성 원천세 조정 809.6백만원 – 10월 원천세 납부 시 정산 예정(예수금 증가와 대응) 2. 공급업체 선급금 415백만원: 협회 후원금 334백만원 신규, CSU 연구비·IRB 심사비 66백만원. 30일 초과 8건(90일 초과 3건) → 비용처리 시기 및 회수가능성 확인 필요 | L19: =E19-F19 -> 0 | N19: =SUMIF('BS_DEC 2026'!$D:$D,$D19,'BS_DEC 2026'!$E:$E) -> 1159433436 | O19: =E19-N19 -> 0 | P19: =SUMIF('BS_DEC 2026'!$D:$D,$D19,'BS_DEC 2026'!$K:$K) -> 1159433436 | Q19: =F19-P19 -> 0
B20: 8. Provisional payment. | C20: 8. | D20: 가지급금 | E20: =SUMIF(FS_map!$H:$H,$D20,FS_map!$M:$M) -> 0 | F20: =SUMIF(FS_map!$H:$H,$D20,FS_map!$P:$P) -> 0 | G20: =SUMIF(WBS_2025YE!$D:$D,$D20,WBS_2025YE!$K:$K) -> 0 | H20: =F20-G20 -> 0 | I20: =IFERROR(H20/G20,IF(H20>0,100%,IF(H20=0,0,-100%))) -> 0 | J20: =IF(AND(ABS(H20)>$J$5,ABS(I20)>5%),"O","") | L20: =E20-F20 -> 0 | N20: =SUMIF('BS_DEC 2026'!$D:$D,$D20,'BS_DEC 2026'!$E:$E) -> 0 | O20: =E20-N20 -> 0 | P20: =SUMIF('BS_DEC 2026'!$D:$D,$D20,'BS_DEC 2026'!$K:$K) -> 0 | Q20: =F20-P20 -> 0
B21: 9. Loan. | C21: 9. | D21: 대여금 | E21: =SUMIF(FS_map!$H:$H,$D21,FS_map!$M:$M) -> 0 | F21: =SUMIF(FS_map!$H:$H,$D21,FS_map!$P:$P) -> 0 | G21: =SUMIF(WBS_2025YE!$D:$D,$D21,WBS_2025YE!$K:$K) -> 0 | H21: =F21-G21 -> 0 | I21: =IFERROR(H21/G21,IF(H21>0,100%,IF(H21=0,0,-100%))) -> 0 | J21: =IF(AND(ABS(H21)>$J$5,ABS(I21)>5%),"O","") | L21: =E21-F21 -> 0 | N21: =SUMIF('BS_DEC 2026'!$D:$D,$D21,'BS_DEC 2026'!$E:$E) -> 0 | O21: =E21-N21 -> 0 | P21: =SUMIF('BS_DEC 2026'!$D:$D,$D21,'BS_DEC 2026'!$K:$K) -> 0 | Q21: =F21-P21 -> 0
B22: 10. Advance payment. | C22: 10. | D22: 선급비용 | E22: =SUMIF(FS_map!$H:$H,$D22,FS_map!$M:$M) -> 1049728634 | F22: =SUMIF(FS_map!$H:$H,$D22,FS_map!$P:$P) -> 1049728634 | G22: =SUMIF(WBS_2025YE!$D:$D,$D22,WBS_2025YE!$K:$K) -> 307501499 | H22: =F22-G22 -> 742227135 | I22: =IFERROR(H22/G22,IF(H22>0,100%,IF(H22=0,0,-100%))) -> 2.413735 | J22: =IF(AND(ABS(H22)>$J$5,ABS(I22)>5%),"O","") | K22: 전기말 308백만원 → 9월말 1,050백만원 1. OneCASA 임상 선급비용 657백만원 신규 (R&D non-PO) 2. 연회비(26.1~12월) 358백만원, 단체보험(26.7~27.6) 236백만원 등을 신규로 선급하고 월할 상각 - 신규 선급 +742백만원, 상각 −657백만원 (2026 단체보험 −170, 연회비 −268, 사이버보험 −55, 운송보험 −53백만원 등) | L22: =E22-F22 -> 0 | N22: =SUMIF('BS_DEC 2026'!$D:$D,$D22,'BS_DEC 2026'!$E:$E) -> 1049728634 | O22: =E22-N22 -> 0 | P22: =SUMIF('BS_DEC 2026'!$D:$D,$D22,'BS_DEC 2026'!$K:$K) -> 1049728634 | Q22: =F22-P22 -> 0
B23: 11. Liquidity Annual Tax Assets | C23: 11. | D23: 유동성이연법인세자산 | E23: =SUMIF(FS_map!$H:$H,$D23,FS_map!$M:$M) -> 19467726192 | F23: =SUMIF(FS_map!$H:$H,$D23,FS_map!$P:$P) -> 19467726192 | G23: =SUMIF(WBS_2025YE!$D:$D,$D23,WBS_2025YE!$K:$K) -> 24194603240 | H23: =F23-G23 -> -4726877048 | I23: =IFERROR(H23/G23,IF(H23>0,100%,IF(H23=0,0,-100%))) -> -0.19536907 | J23: =IF(AND(ABS(H23)>$J$5,ABS(I23)>5%),"O","") | K23: 전기말 242억원 → 9월말 195억원 (−47억원) 1. 3분기 법인세 추정에 따른 이연법인세 감소 −5,791백만원 2. 법인세율 변경(23.1% → 24.2%)에 따른 기초 이연법인세자산 재측정 +1,163백만원 (244억 → 256억원) 3. 로컬 조정(86291000) −317백만원 ※ 중간기간 이연법인세는 회사 추정치이므로 기말 세무조정 후 재검토 필요 | L23: =E23-F23 -> 0 | N23: =SUMIF('BS_DEC 2026'!$D:$D,$D23,'BS_DEC 2026'!$E:$E) -> 19467726192 | O23: =E23-N23 -> 0 | P23: =SUMIF('BS_DEC 2026'!$D:$D,$D23,'BS_DEC 2026'!$K:$K) -> 19467726192 | Q23: =F23-P23 -> 0
B24: 12. National Pension Conversion Assets | C24: 12. | D24: 국민연금전환금자산 | E24: =SUMIF(FS_map!$H:$H,$D24,FS_map!$M:$M) -> 0 | F24: =SUMIF(FS_map!$H:$H,$D24,FS_map!$P:$P) -> 0 | G24: =SUMIF(WBS_2025YE!$D:$D,$D24,WBS_2025YE!$K:$K) -> 0 | H24: =F24-G24 -> 0 | I24: =IFERROR(H24/G24,IF(H24>0,100%,IF(H24=0,0,-100%))) -> 0 | J24: =IF(AND(ABS(H24)>$J$5,ABS(I24)>5%),"O","") | L24: =E24-F24 -> 0 | N24: =SUMIF('BS_DEC 2026'!$D:$D,$D24,'BS_DEC 2026'!$E:$E) -> 0 | O24: =E24-N24 -> 0 | P24: =SUMIF('BS_DEC 2026'!$D:$D,$D24,'BS_DEC 2026'!$K:$K) -> 0 | Q24: =F24-P24 -> 0
C25: 13 | D25: 유동성보증금 | E25: =SUMIF(FS_map!$H:$H,$D25,FS_map!$M:$M) -> 0 | F25: =SUMIF(FS_map!$H:$H,$D25,FS_map!$P:$P) -> 0 | G25: =SUMIF(WBS_2025YE!$D:$D,$D25,WBS_2025YE!$K:$K) -> 0 | H25: =F25-G25 -> 0 | I25: =IFERROR(H25/G25,IF(H25>0,100%,IF(H25=0,0,-100%))) -> 0 | J25: =IF(AND(ABS(H25)>$J$5,ABS(I25)>5%),"O","") | L25: =E25-F25 -> 0 | N25: =SUMIF('BS_DEC 2026'!$D:$D,$D25,'BS_DEC 2026'!$E:$E) -> 0 | O25: =E25-N25 -> 0 | P25: =SUMIF('BS_DEC 2026'!$D:$D,$D25,'BS_DEC 2026'!$K:$K) -> 0 | Q25: =F25-P25 -> 0
I26: =IFERROR(H26/G26,IF(H26>0,100%,IF(H26=0,0,-100%))) -> 0 | J26: =IF(AND(ABS(H26)>$J$5,ABS(I26)>5%),"O","") | L26: =E26-F26 -> 0
B27: (2) Inventory assets. | C27: (2) 재고자산 | E27: =SUM(E28:E37) -> 195439963106 | F27: =SUM(F28:F37) -> 195439963106 | G27: =SUM(G28:G37) -> 176435792670 | H27: =SUM(H28:H37) -> 19004170436 | I27: =IFERROR(H27/G27,IF(H27>0,100%,IF(H27=0,0,-100%))) -> 0.10771154 | J27: =IF(AND(ABS(H27)>$J$5,ABS(I27)>5%),"O","") -> O | K27: 재고회전일수(연환산 매출원가 기준) 131일(전기말 128일). 세부 내역은 상품·평가충당금·미착품 코멘트 참조 | L27: =E27-F27 -> 0 | N27: =SUM(N28:N37) -> 195439963106 | O27: =E27-N27 -> 0 | P27: =SUM(P28:P37) -> 195439963106 | Q27: =F27-P27 -> 0
B28: 1. Prize. | C28: 1. | D28: 상품 | E28: =SUMIF(FS_map!$H:$H,$D28,FS_map!$M:$M) -> 180063595464 | F28: =SUMIF(FS_map!$H:$H,$D28,FS_map!$P:$P) -> 180063595464 | G28: =SUMIF(WBS_2025YE!$D:$D,$D28,WBS_2025YE!$K:$K) -> 160568039290 | H28: =F28-G28 -> 19495556174 | I28: =IFERROR(H28/G28,IF(H28>0,100%,IF(H28=0,0,-100%))) -> 0.12141617 | J28: =IF(AND(ABS(H28)>$J$5,ABS(I28)>5%),"O","") -> O | K28: 전기말 1,606억원 → 9월말 1,801억원 (+195억원) 1. Pharma 1,166억 → 1,263억원(+97억원): Taxotere MA 이전 프로젝트에 대비한 재고 선확보(stock piling) +90억원 2. Vaccines 440억 → 538억원(+98억원): Pentaxim → Hexaxim 전환에 따른 Hexaxim 재고 +70억원, Beyfortus 시즌 재고 +80억원 3. 원가차이 자본화(20000030) −17억 → −9억원 (출처: 회사 BS 분석적검토 – 상품수불부 기준) | L28: =E28-F28 -> 0 | N28: =SUMIF('BS_DEC 2026'!$D:$D,$D28,'BS_DEC 2026'!$E:$E) -> 180063595464 | O28: =E28-N28 -> 0 | P28: =SUMIF('BS_DEC 2026'!$D:$D,$D28,'BS_DEC 2026'!$K:$K) -> 180063595464 | Q28: =F28-P28 -> 0
B29: Evaluation allowance - product | D29: 평가충당금-상품 | E29: =SUMIF(FS_map!$H:$H,$D29,FS_map!$M:$M) -> -2420155943 | F29: =SUMIF(FS_map!$H:$H,$D29,FS_map!$P:$P) -> -2420155943 | G29: =SUMIF(WBS_2025YE!$D:$D,$D29,WBS_2025YE!$K:$K) -> -4823897784 | H29: =F29-G29 -> 2403741841 | I29: =IFERROR(H29/G29,IF(H29>0,100%,IF(H29=0,0,-100%))) -> -0.49829867 | J29: =IF(AND(ABS(H29)>$J$5,ABS(I29)>5%),"O","") | K29: 전기말 48.2억원 → 9월말 24.2억원 (24억원 감소) 1. Pharma 1.6억 → 8.6억원: Dupixent(2억원) 등 유효기간 반품 및 단종 품목에 대한 충당금 증가 2. Vaccines 46.1억 → 15.1억원: Pentaxim 수요 증가로 기존 충당 재고 소진, Efluelda 유효기간 반품 감소 ※ 전기말 충당 재고의 당기 폐기·판매 내역 확인 필요 | L29: =E29-F29 -> 0 | N29: =SUMIF('BS_DEC 2026'!$D:$D,$D29,'BS_DEC 2026'!$E:$E) -> -2420155943 | O29: =E29-N29 -> 0 | P29: =SUMIF('BS_DEC 2026'!$D:$D,$D29,'BS_DEC 2026'!$K:$K) -> -2420155943 | Q29: =F29-P29 -> 0
B30: 2. Product. | C30: 2. | D30: 제품 | E30: =SUMIF(FS_map!$H:$H,$D30,FS_map!$M:$M) -> 0 | F30: =SUMIF(FS_map!$H:$H,$D30,FS_map!$P:$P) -> 0 | G30: =SUMIF(WBS_2025YE!$D:$D,$D30,WBS_2025YE!$K:$K) -> 0 | H30: =F30-G30 -> 0 | I30: =IFERROR(H30/G30,IF(H30>0,100%,IF(H30=0,0,-100%))) -> 0 | J30: =IF(AND(ABS(H30)>$J$5,ABS(I30)>5%),"O","") | L30: =E30-F30 -> 0 | N30: =SUMIF('BS_DEC 2026'!$D:$D,$D30,'BS_DEC 2026'!$E:$E) -> 0 | O30: =E30-N30 -> 0 | P30: =SUMIF('BS_DEC 2026'!$D:$D,$D30,'BS_DEC 2026'!$K:$K) -> 0 | Q30: =F30-P30 -> 0
B31: Evaluation allowance - product | D31: 평가충당금-제품 | E31: =SUMIF(FS_map!$H:$H,$D31,FS_map!$M:$M) -> 0 | F31: =SUMIF(FS_map!$H:$H,$D31,FS_map!$P:$P) -> 0 | G31: =SUMIF(WBS_2025YE!$D:$D,$D31,WBS_2025YE!$K:$K) -> 0 | H31: =F31-G31 -> 0 | I31: =IFERROR(H31/G31,IF(H31>0,100%,IF(H31=0,0,-100%))) -> 0 | J31: =IF(AND(ABS(H31)>$J$5,ABS(I31)>5%),"O","") | L31: =E31-F31 -> 0 | N31: =SUMIF('BS_DEC 2026'!$D:$D,$D31,'BS_DEC 2026'!$E:$E) -> 0 | O31: =E31-N31 -> 0 | P31: =SUMIF('BS_DEC 2026'!$D:$D,$D31,'BS_DEC 2026'!$K:$K) -> 0 | Q31: =F31-P31 -> 0
B32: 3. Reproduct. | C32: 3. | D32: 재공품 | E32: =SUMIF(FS_map!$H:$H,$D32,FS_map!$M:$M) -> 0 | F32: =SUMIF(FS_map!$H:$H,$D32,FS_map!$P:$P) -> 0 | G32: =SUMIF(WBS_2025YE!$D:$D,$D32,WBS_2025YE!$K:$K) -> 0 | H32: =F32-G32 -> 0 | I32: =IFERROR(H32/G32,IF(H32>0,100%,IF(H32=0,0,-100%))) -> 0 | J32: =IF(AND(ABS(H32)>$J$5,ABS(I32)>5%),"O","") | L32: =E32-F32 -> 0 | N32: =SUMIF('BS_DEC 2026'!$D:$D,$D32,'BS_DEC 2026'!$E:$E) -> 0 | O32: =E32-N32 -> 0 | P32: =SUMIF('BS_DEC 2026'!$D:$D,$D32,'BS_DEC 2026'!$K:$K) -> 0 | Q32: =F32-P32 -> 0
B33: 4. Raw materials. | C33: 4. | D33: 원재료 | E33: =SUMIF(FS_map!$H:$H,$D33,FS_map!$M:$M) -> 0 | F33: =SUMIF(FS_map!$H:$H,$D33,FS_map!$P:$P) -> 0 | G33: =SUMIF(WBS_2025YE!$D:$D,$D33,WBS_2025YE!$K:$K) -> 0 | H33: =F33-G33 -> 0 | I33: =IFERROR(H33/G33,IF(H33>0,100%,IF(H33=0,0,-100%))) -> 0 | J33: =IF(AND(ABS(H33)>$J$5,ABS(I33)>5%),"O","") | L33: =E33-F33 -> 0 | N33: =SUMIF('BS_DEC 2026'!$D:$D,$D33,'BS_DEC 2026'!$E:$E) -> 0 | O33: =E33-N33 -> 0 | P33: =SUMIF('BS_DEC 2026'!$D:$D,$D33,'BS_DEC 2026'!$K:$K) -> 0 | Q33: =F33-P33 -> 0
B34: Evaluation allowance - raw material. | D34: 평가충당금-원재료 | E34: =SUMIF(FS_map!$H:$H,$D34,FS_map!$M:$M) -> 0 | F34: =SUMIF(FS_map!$H:$H,$D34,FS_map!$P:$P) -> 0 | G34: =SUMIF(WBS_2025YE!$D:$D,$D34,WBS_2025YE!$K:$K) -> 0 | H34: =F34-G34 -> 0 | I34: =IFERROR(H34/G34,IF(H34>0,100%,IF(H34=0,0,-100%))) -> 0 | J34: =IF(AND(ABS(H34)>$J$5,ABS(I34)>5%),"O","") | L34: =E34-F34 -> 0 | N34: =SUMIF('BS_DEC 2026'!$D:$D,$D34,'BS_DEC 2026'!$E:$E) -> 0 | O34: =E34-N34 -> 0 | P34: =SUMIF('BS_DEC 2026'!$D:$D,$D34,'BS_DEC 2026'!$K:$K) -> 0 | Q34: =F34-P34 -> 0
B35: 5. Packaging ingredients. | C35: 5. | D35: 포장재료 | E35: =SUMIF(FS_map!$H:$H,$D35,FS_map!$M:$M) -> 0 | F35: =SUMIF(FS_map!$H:$H,$D35,FS_map!$P:$P) -> 0 | G35: =SUMIF(WBS_2025YE!$D:$D,$D35,WBS_2025YE!$K:$K) -> 0 | H35: =F35-G35 -> 0 | I35: =IFERROR(H35/G35,IF(H35>0,100%,IF(H35=0,0,-100%))) -> 0 | J35: =IF(AND(ABS(H35)>$J$5,ABS(I35)>5%),"O","") | L35: =E35-F35 -> 0 | N35: =SUMIF('BS_DEC 2026'!$D:$D,$D35,'BS_DEC 2026'!$E:$E) -> 0 | O35: =E35-N35 -> 0 | P35: =SUMIF('BS_DEC 2026'!$D:$D,$D35,'BS_DEC 2026'!$K:$K) -> 0 | Q35: =F35-P35 -> 0
B36: Evaluation allowance - Packaging material | D36: 평가충당금-포장재료 | E36: =SUMIF(FS_map!$H:$H,$D36,FS_map!$M:$M) -> 0 | F36: =SUMIF(FS_map!$H:$H,$D36,FS_map!$P:$P) -> 0 | G36: =SUMIF(WBS_2025YE!$D:$D,$D36,WBS_2025YE!$K:$K) -> 0 | H36: =F36-G36 -> 0 | I36: =IFERROR(H36/G36,IF(H36>0,100%,IF(H36=0,0,-100%))) -> 0 | J36: =IF(AND(ABS(H36)>$J$5,ABS(I36)>5%),"O","") | L36: =E36-F36 -> 0 | N36: =SUMIF('BS_DEC 2026'!$D:$D,$D36,'BS_DEC 2026'!$E:$E) -> 0 | O36: =E36-N36 -> 0 | P36: =SUMIF('BS_DEC 2026'!$D:$D,$D36,'BS_DEC 2026'!$K:$K) -> 0 | Q36: =F36-P36 -> 0
B37: 6. Not received. | C37: 6. | D37: 미착품 | E37: =SUMIF(FS_map!$H:$H,$D37,FS_map!$M:$M) -> 17796523585 | F37: =SUMIF(FS_map!$H:$H,$D37,FS_map!$P:$P) -> 17796523585 | G37: =SUMIF(WBS_2025YE!$D:$D,$D37,WBS_2025YE!$K:$K) -> 20691651164 | H37: =F37-G37 -> -2895127579 | I37: =IFERROR(H37/G37,IF(H37>0,100%,IF(H37=0,0,-100%))) -> -0.13991767 | J37: =IF(AND(ABS(H37)>$J$5,ABS(I37)>5%),"O","") | K37: 전기말 207억원 → 9월말 178억원 (−29억원, GR/IR 40500001 기준) 1. Pharma 미착품 203억 → 147억원: Multaq(−40억원), Toujeo(−20억원) 선적 시점 차이 2. Vaccines 미착품 4억 → 32억원: Adacel 선적 진행분 ※ 기말 cut-off 검토 시 선적조건(인도기준) 확인 필요 | L37: =E37-F37 -> 0 | N37: =SUMIF('BS_DEC 2026'!$D:$D,$D37,'BS_DEC 2026'!$E:$E) -> 17796523585 | O37: =E37-N37 -> 0 | P37: =SUMIF('BS_DEC 2026'!$D:$D,$D37,'BS_DEC 2026'!$K:$K) -> 17796523585 | Q37: =F37-P37 -> 0
I38: =IFERROR(H38/G38,IF(H38>0,100%,IF(H38=0,0,-100%))) -> 0 | J38: =IF(AND(ABS(H38)>$J$5,ABS(I38)>5%),"O","") | L38: =E38-F38 -> 0
B39: II. Fixed assets. | C39: II. 고정자산 | E39: =+E44+E40+E58+E66+E73 -> 3546064105 | F39: =+F44+F40+F58+F66+F73 -> 3546064105 | G39: =+G44+G40+G58+G66+G73 -> 3167547191 | H39: =+H44+H40+H58+H66+H73 -> 378516914 | I39: =IFERROR(H39/G39,IF(H39>0,100%,IF(H39=0,0,-100%))) -> 0.11949843 | L39: =E39-F39 -> 0 | N39: =+N44+N40+N58+N66+N73 -> 3546064105 | O39: =E39-N39 -> 0 | P39: =+P44+P40+P58+P66+P73 -> 3546064105 | Q39: =F39-P39 -> 0
B40: (1) Investment assets. | C40: (1) 투자자산 | E40: =SUM(E41:E43) -> 0 | F40: =SUM(F41:F43) -> 30000000 | G40: =SUM(G41:G43) -> 30000000 | H40: =SUM(H41:H43) -> 0 | I40: =IFERROR(H40/G40,IF(H40>0,100%,IF(H40=0,0,-100%))) -> 0 | J40: =IF(AND(ABS(H40)>$J$5,ABS(I40)>5%),"O","") | L40: =E40-F40 -> -30000000 | N40: =SUM(N41:N43) -> 0 | O40: =E40-N40 -> 0 | P40: =SUM(P41:P43) -> 30000000 | Q40: =F40-P40 -> 0
B41: 1. Long-term financial instruments. | C41: 1. | D41: 장기금융상품 | E41: =SUMIF(FS_map!$H:$H,$D41,FS_map!$M:$M) -> 0 | F41: =SUMIF(FS_map!$H:$H,$D41,FS_map!$P:$P) -> 0 | G41: =SUMIF(WBS_2025YE!$D:$D,$D41,WBS_2025YE!$K:$K) -> 0 | H41: =F41-G41 -> 0 | I41: =IFERROR(H41/G41,IF(H41>0,100%,IF(H41=0,0,-100%))) -> 0 | J41: =IF(AND(ABS(H41)>$J$5,ABS(I41)>5%),"O","") | L41: =E41-F41 -> 0 | N41: =SUMIF('BS_DEC 2026'!$D:$D,$D41,'BS_DEC 2026'!$E:$E) -> 0 | O41: =E41-N41 -> 0 | P41: =SUMIF('BS_DEC 2026'!$D:$D,$D41,'BS_DEC 2026'!$K:$K) -> 0 | Q41: =F41-P41 -> 0
C42: 2. | D42: 지분법적용투자주식 | E42: =SUMIF(FS_map!$H:$H,$D42,FS_map!$M:$M) -> 0 | F42: =SUMIF(FS_map!$H:$H,$D42,FS_map!$P:$P) -> 0 | G42: =SUMIF(WBS_2025YE!$D:$D,$D42,WBS_2025YE!$K:$K) -> 0 | H42: =F42-G42 -> 0 | I42: =IFERROR(H42/G42,IF(H42>0,100%,IF(H42=0,0,-100%))) -> 0 | J42: =IF(AND(ABS(H42)>$J$5,ABS(I42)>5%),"O","") | L42: =E42-F42 -> 0 | N42: =SUMIF('BS_DEC 2026'!$D:$D,$D42,'BS_DEC 2026'!$E:$E) -> 0 | O42: =E42-N42 -> 0 | P42: =SUMIF('BS_DEC 2026'!$D:$D,$D42,'BS_DEC 2026'!$K:$K) -> 0 | Q42: =F42-P42 -> 0
...

Sheet P&L_KO
C2: 손익계산서
C4: =+BS_KO!C4 -> 제 37(당) 기 2026년 12월 31일 현재 | I4: OM | J4: 0.01 | K4: =G10*J4 -> 7.0976202e+09 | L4: 벤치마크: 매출액
C5: =+BS_KO!C5 -> 제 36(전) 기 2025년 12월 31일 현재 | I5: PM | J5: 0.8 | K5: =K4*J5 -> 5.6780962e+09
I6: CTT | J6: 0.03 | K6: =K4*J6 -> 2.1292861e+08
C7: =+BS_KO!C7 -> 주식회사 사노피-아벤티스코리아
C8: 과목 | E8: =BS_KO!E8 -> 2026.09 | G8: 2026.09 | H8: =BS_KO!G8 -> 2025.12 | U8: 회사 F/S 대사 (PL_DEC.2026)
E9: 수정전 | F9: 수정후 | G9: 연환산 | H9: 금액 | I9: Var. | J9: Var. % | K9: 증감분석여부? | L9: 증감분석 | U9: 회사 SAP(E열) | V9: Diff (E-U) | W9: 회사 Statutory(L열) | X9: Diff (F-W)
C10: I. 매출액 | E10: =SUM(E11:E12) -> 532321516164 | F10: =SUM(F11:F12) -> 532321516164 | G10: =F10*12/9 -> 709762021552 | H10: =SUM(H11:H12) -> 645754460671 | I10: =G10-H10 -> 64007560881 | J10: =IFERROR(I10/H10,IF(I10>0,100%,IF(I10=0,0,-100%))) -> 0.099120587 | N10: =+F10/H10-1 -> -0.17565956 | U10: =SUM(U11:U12) -> 532321516164 | V10: =E10-U10 -> 0 | W10: =SUM(W11:W12) -> 532321516164 | X10: =F10-W10 -> 0
C11: 1. | D11: 매출액 | E11: =SUMIF(FS_map!$H:$H,$D11,FS_map!$M:$M)*-1 -> 532321516164 | F11: =SUMIF(FS_map!$H:$H,$D11,FS_map!$P:$P)*-1 -> 532321516164 | G11: =F11*12/9 -> 709762021552 | H11: =SUMIF(WPL_2025YE!$D:$D,$D11,WPL_2025YE!$AI:$AI) -> 645754460671 | I11: =G11-H11 -> 64007560881 | J11: =IFERROR(I11/H11,IF(I11>0,100%,IF(I11=0,0,-100%))) -> 0.099120587 | K11: =IF(AND(ABS(I11)>$K$5,ABS(J11)>5%),"O","") -> O | L11: 9월 누적 5,323억원 (전년 동기 4,991억원 대비 +333억원, +6.7%), 연환산 7,098억원 (전기 6,458억원 대비 +640억원, +9.9%) 1. 총매출 +475억원 (회사 IFRS 분석 기준) 1) Pharma +368억원: Dupixent +160억원(AS 적응증 급여, COPD 출시, 환자 수 증가), Rezurock +145억원(급여 출시), Plavix +75억원(의료파업 영향) 2) Vaccines −3억원: Beyfortus +273억원, Hexaxim +122억원(Pentaxim 전환 및 출생아 증가), Menquadfi +68억원(군납 조기주문) vs Vaxigrip −299억원(공급 제약), 기타 제품 믹스 −166억원 3) 글로벌 divestment 품목은 MA 이전 완료 전까지 매출에 포함: Taxotere 94억원, Carprelsa 16억원 2. 매출차감 - 시장접근(MA) 약정 546억원 (전년 동기 412억원, Dupixent·Rezurock 증가) - 입찰/가격조정 115억원 (전년 동기 193억원, Vaxigrip 공급 제약) - 판매장려금 658억원 (전년 동기 562억원, Eloxatin·Plavix 판매 증가) - 반품 30억원 (Taxotere 품질이슈 회수 등) 3. 관계사 수출 매출 8.4억원 (Sanofi Winthrop, Menquadfi QC 실패 관련 수출) (출처: 회사 PL 분석적검토 – YTD Sep'26 vs YTD Sep'25) | M11: =E11-F11 -> 0 | N11: =+F11/H11-1 -> -0.17565956 | U11: =SUMIF('PL_DEC.2026'!$D:$D,$D11,'PL_DEC.2026'!$E:$E) -> 532321516164 | V11: =E11-U11 -> 0 | W11: =SUMIF('PL_DEC.2026'!$D:$D,$D11,'PL_DEC.2026'!$L:$L) -> 532321516164 | X11: =F11-W11 -> 0
C12: 2. | D12: 용역수익 | E12: =SUMIF(FS_map!$H:$H,$D12,FS_map!$M:$M)*-1 -> 0 | F12: =SUMIF(FS_map!$H:$H,$D12,FS_map!$P:$P)*-1 -> 0 | G12: =F12*12/9 -> 0 | H12: =SUMIF(WPL_2025YE!$D:$D,$D12,WPL_2025YE!$AI:$AI) -> 0 | I12: =G12-H12 -> 0 | J12: =IFERROR(I12/H12,IF(I12>0,100%,IF(I12=0,0,-100%))) -> 0 | K12: =IF(AND(ABS(I12)>$K$5,ABS(J12)>5%),"O","") | M12: =E12-F12 -> 0 | U12: =SUMIF('PL_DEC.2026'!$D:$D,$D12,'PL_DEC.2026'!$E:$E) -> 0 | V12: =E12-U12 -> 0 | W12: =SUMIF('PL_DEC.2026'!$D:$D,$D12,'PL_DEC.2026'!$L:$L) -> 0 | X12: =F12-W12 -> 0
C13: II. 매출원가 | E13: =+E14+E23+E31 -> 401363779478 | F13: =+F14+F23+F31 -> 401363779478 | G13: =G14 -> 542995529309 | H13: =+H14+H23+H31 -> 501702262547 | I13: =G13-H13 -> 41293266762 | J13: =IFERROR(I13/H13,IF(I13>0,100%,IF(I13=0,0,-100%))) -> 0.08230632 | M13: =E13-F13 -> 0 | N13: =+F13/F10 -> 0.75398752 | O13: =+H13/H10 -> 0.77692419 | U13: =+U14+U23+U31 -> 401363779478 | V13: =E13-U13 -> 0 | W13: =+W14+W23+W31 -> 401771822503 | X13: =F13-W13 -> -408043025
C14: (1) | D14: 상품매출원가 | E14: =SUMIF(FS_map!$H:$H,$D14,FS_map!$M:$M) -> 401363779478 | F14: =SUMIF(FS_map!$H:$H,$D14,FS_map!$P:$P) -> 401363779478 | G14: =SUM(G20:G22) -> 542995529309 | H14: =SUMIF(WPL_2025YE!$D:$D,$D14,WPL_2025YE!$AI:$AI) -> 501702262547 | I14: =G14-H14 -> 41293266762 | J14: =IFERROR(I14/H14,IF(I14>0,100%,IF(I14=0,0,-100%))) -> 0.08230632 | K14: =IF(AND(ABS(I14)>$K$5,ABS(J14)>5%),"O","") -> O | L14: 9월 누적 4,014억원 (전년 동기 3,748억원 대비 +266억원). 매출원가율 75.4% (전년 동기 75.1%, 전기 77.7%) 1. 매출 증가에 따른 원가 증가가 주요인. 회사 IFRS 기준 매출원가 +293억원이며, 회사는 매출총이익률을 그룹 TP 정책에 따라 월별로 관리함 2. 수불부 대사: 수불부 매출원가 4,018억원과 GL 상품매출원가의 차이 −4.1억원은 86000800(P16, 전기 TP조정 408백만원 reversal)으로 설명됨 (N14 = 0) 3. 관계사 전기 TP조정 비용 30.2억원과 백신 TP credit note −26.2억원은 잡손실로 분류됨 → 매출원가 해당 여부 검토 필요 4. 수불부 타계정(매입가격차이) 산식에 회사가 확인한 오류 −5.2억원 포함 (10월 수정 예정) | M14: =E14-F14 -> 0 | N14: =+F14-R22-SUMIF(FS_map!$D:$D,"86000800",FS_map!$P:$P) -> 0 | O14: ← 0이어야 함 (SAP 상품매출원가 = 수불부 매출원가 + 86000800 P16 reversal) | U14: =SUMIF('PL_DEC.2026'!$D:$D,$D14,'PL_DEC.2026'!$E:$E) -> 401363779478 | V14: =E14-U14 -> 0 | W14: =SUMIF('PL_DEC.2026'!$D:$D,$D14,'PL_DEC.2026'!$L:$L) -> 401771822503 | X14: =F14-W14 -> -408043025
C15: 1. | D15: 기초상품재고액 | E15: =R17 -> 155744141506 | F15: =R17 -> 155744141506 | G15: =F15 -> 155744141506 | H15: =SUMIF(WPL_2025YE!$D:$D,$D15,WPL_2025YE!$AI:$AI) -> 160701424589 | I15: =G15-H15 -> -4957283083 | J15: =IFERROR(I15/H15,IF(I15>0,100%,IF(I15=0,0,-100%))) -> -0.030847786 | M15: =E15-F15 -> 0 | Q15: <상품수불부> | U15: =W15 -> 155744141506 | V15: =E15-U15 -> 0 | W15: =SUMIF('PL_DEC.2026'!$D:$D,$D15,'PL_DEC.2026'!$L:$L) -> 155744141506 | X15: =F15-W15 -> 0
D16: 합병으로인한전입액 | E16: =SUMIF(FS_map!$H:$H,$D16,FS_map!$M:$M) -> 0 | F16: =SUMIF(FS_map!$H:$H,$D16,FS_map!$P:$P) -> 0 | G16: =F16*12/9 -> 0 | H16: =SUMIF(WPL_2025YE!$D:$D,$D16,WPL_2025YE!$AI:$AI) -> 0 | I16: =G16-H16 -> 0 | J16: =IFERROR(I16/H16,IF(I16>0,100%,IF(I16=0,0,-100%))) -> 0 | K16: =IF(AND(ABS(I16)>$K$5,ABS(J16)>5%),"O","") | M16: =E16-F16 -> 0 | Q16: 구분 | R16: <'26년9월말> | U16: =SUMIF('PL_DEC.2026'!$D:$D,$D16,'PL_DEC.2026'!$E:$E) -> 0 | V16: =E16-U16 -> 0 | W16: =SUMIF('PL_DEC.2026'!$D:$D,$D16,'PL_DEC.2026'!$L:$L) -> 0 | X16: =F16-W16 -> 0
C17: 2. | D17: 당기상품매입액 | E17: =$R$18 -> 423703487976 | F17: =$R$18 -> 423703487976 | G17: =F17*12/9 -> 564937983968 | H17: =SUMIF(WPL_2025YE!$D:$D,$D17,WPL_2025YE!$AI:$AI) -> 497042768857 | I17: =G17-H17 -> 67895215111 | J17: =IFERROR(I17/H17,IF(I17>0,100%,IF(I17=0,0,-100%))) -> 0.13659834 | K17: =IF(AND(ABS(I17)>$K$5,ABS(J17)>5%),"O","") -> O | L17: 9월 누적 4,237억원 (전년 동기 3,664억원 대비 +573억원), 연환산 5,649억원 (전기 4,970억원) 1. 매출 증가 및 재고 증가(기말상품 +219억원: Taxotere MA 이전 대비 선확보 90억원, Hexaxim·Beyfortus 시즌재고 150억원)에 따른 매입 증가 2. 관계사 매입채무(Sanofi-Aventis Singapore) 874억원 증가와 일관됨 3. 매입가격차이(타계정) −10.5억원 포함 | M17: =E17-F17 -> 0 | Q17: 기초 | R17: =H22*-1 -> 155744141506 | U17: =W17 -> 423703488001 | V17: =E17-U17 -> -25 | W17: =SUMIF('PL_DEC.2026'!$D:$D,$D17,'PL_DEC.2026'!$L:$L) -> 423703488001 | X17: =F17-W17 -> -25
D18: 관세환급금 | E18: =SUMIF(FS_map!$H:$H,$D18,FS_map!$M:$M) -> 0 | F18: =SUMIF(FS_map!$H:$H,$D18,FS_map!$P:$P) -> 0 | G18: =F18*12/9 -> 0 | H18: =SUMIF(WPL_2025YE!$D:$D,$D18,WPL_2025YE!$AI:$AI) -> 0 | I18: =G18-H18 -> 0 | J18: =IFERROR(I18/H18,IF(I18>0,100%,IF(I18=0,0,-100%))) -> 0 | K18: =IF(AND(ABS(I18)>$K$5,ABS(J18)>5%),"O","") | M18: =E18-F18 -> 0 | N18: =(+F15+F17+F21+F22)-F14 -> 408043000 | Q18: 입고 | R18: =+R19+R20 -> 423703487976 | U18: =SUMIF('PL_DEC.2026'!$D:$D,$D18,'PL_DEC.2026'!$E:$E) -> 0 | V18: =E18-U18 -> 0 | W18: =SUMIF('PL_DEC.2026'!$D:$D,$D18,'PL_DEC.2026'!$L:$L) -> 0 | X18: =F18-W18 -> 0
C19: 3. | D19: 타계정에서대체-상품 | E19: =SUMIF(FS_map!$H:$H,$D19,FS_map!$M:$M) -> 0 | F19: =SUMIF(FS_map!$H:$H,$D19,FS_map!$P:$P) -> 0 | G19: =F19*12/9 -> 0 | H19: =SUMIF(WPL_2025YE!$D:$D,$D19,WPL_2025YE!$AI:$AI) -> 0 | I19: =G19-H19 -> 0 | J19: =IFERROR(I19/H19,IF(I19>0,100%,IF(I19=0,0,-100%))) -> 0 | K19: =IF(AND(ABS(I19)>$K$5,ABS(J19)>5%),"O","") | M19: =E19-F19 -> 0 | Q19: 상품매입 | R19: ='PL_DEC.2026'!R5 -> 424753563203 | S19: Q | U19: =SUMIF('PL_DEC.2026'!$D:$D,$D19,'PL_DEC.2026'!$E:$E) -> 0 | V19: =E19-U19 -> 0 | W19: =SUMIF('PL_DEC.2026'!$D:$D,$D19,'PL_DEC.2026'!$L:$L) -> 0 | X19: =F19-W19 -> 0
D20: 계 | E20: =SUM(E15:E19) -> 579447629482 | F20: =SUM(F15:F19) -> 579447629482 | G20: =SUM(G15:G19) -> 720682125474 | H20: =SUM(H15:H19) -> 657744193446 | I20: =G20-H20 -> 62937932028 | J20: =IFERROR(I20/H20,IF(I20>0,100%,IF(I20=0,0,-100%))) -> 0.095687552 | M20: =E20-F20 -> 0 | Q20: 타계정(매입가격차이) | R20: ='PL_DEC.2026'!R6 -> -1050075227 | S20: T | U20: =SUM(U15:U19) -> 579447629507 | V20: =E20-U20 -> -25 | W20: =SUM(W15:W19) -> 579447629507 | X20: =F20-W20 -> -25
C21: 3. | D21: 타계정으로대체-상품 | E21: =R23*-1 -> -32367483 | F21: =R23*-1 -> -32367483 | G21: =F21*12/9 -> -43156644 | H21: =SUMIF(WPL_2025YE!$D:$D,$D21,WPL_2025YE!$AI:$AI) -> -297789393 | I21: =G21-H21 -> 254632749 | J21: =IFERROR(I21/H21,IF(I21>0,100%,IF(I21=0,0,-100%))) -> -0.85507662 | K21: =IF(AND(ABS(I21)>$K$5,ABS(J21)>5%),"O","") | L21: 견본품 등 타계정 대체 32백만원 (전년 동기 260백만원, 전기 연간 298백만원) | M21: =E21-F21 -> 0 | Q21: 출고 | R21: =+R22+R23 -> 401804189961 | U21: =W21 -> -32367483 | V21: =E21-U21 -> 0 | W21: =SUMIF('PL_DEC.2026'!$D:$D,$D21,'PL_DEC.2026'!$L:$L) -> -32367483 | X21: =F21-W21 -> 0
C22: 4. | D22: 기말상품재고액 | E22: =SUM(BS_KO!E28:E29)*-1 -> -177643439521 | F22: =SUM(BS_KO!F28:F29)*-1 -> -177643439521 | G22: =F22 -> -177643439521 | H22: =SUMIF(WPL_2025YE!$D:$D,$D22,WPL_2025YE!$AI:$AI) -> -155744141506 | I22: =G22-H22 -> -21899298015 | J22: =IFERROR(I22/H22,IF(I22>0,100%,IF(I22=0,0,-100%))) -> 0.14061073 | L22: 기말상품(평가충당금 차감 후) 1,776억원. BS 재고자산 코멘트 참조 | M22: =E22-F22 -> 0 | N22: =+F22=-(BS_KO!F28+BS_KO!F29) -> 1 | Q22: 매출원가 | R22: ='PL_DEC.2026'!R8 -> 401771822478 | S22: AA | U22: =W22 -> -177643439521 | V22: =E22-U22 -> 0 | W22: =SUMIF('PL_DEC.2026'!$D:$D,$D22,'PL_DEC.2026'!$L:$L) -> -177643439521 | X22: =F22-W22 -> 0
C23: (2) 제품매출원가 | E23: =SUMIF(FS_map!$H:$H,"제품매출원가",FS_map!$M:$M) -> 0 | G23: =F23*12/9 -> 0 | H23: =SUMIF(WPL_2025YE!$D:$D,"제품매출원가",WPL_2025YE!$AI:$AI) -> 0 | I23: =G23-H23 -> 0 | J23: =IFERROR(I23/H23,IF(I23>0,100%,IF(I23=0,0,-100%))) -> 0 | K23: =IF(AND(ABS(I23)>$K$5,ABS(J23)>5%),"O","") | M23: =E23-F23 -> 0 | Q23: 타계정 | R23: ='PL_DEC.2026'!R9 -> 32367483 | S23: AD -sampling | U23: =0 -> 0 | V23: =E23-U23 -> 0 | W23: =0 -> 0 | X23: =F23-W23 -> 0
C24: 1. | D24: 기초제품재고액 | G24: =F24*12/9 -> 0 | I24: =G24-H24 -> 0 | J24: =IFERROR(I24/H24,IF(I24>0,100%,IF(I24=0,0,-100%))) -> 0 | K24: =IF(AND(ABS(I24)>$K$5,ABS(J24)>5%),"O","") | M24: =E24-F24 -> 0 | Q24: 기말 | R24: =R17+R18-R21 -> 177643439521
D25: 합병으로인한전입액 | G25: =F25*12/9 -> 0 | I25: =G25-H25 -> 0 | J25: =IFERROR(I25/H25,IF(I25>0,100%,IF(I25=0,0,-100%))) -> 0 | K25: =IF(AND(ABS(I25)>$K$5,ABS(J25)>5%),"O","") | M25: =E25-F25 -> 0
C26: 2. | D26: 당기제품제조원가 | G26: =F26*12/9 -> 0 | I26: =G26-H26 -> 0 | J26: =IFERROR(I26/H26,IF(I26>0,100%,IF(I26=0,0,-100%))) -> 0 | K26: =IF(AND(ABS(I26)>$K$5,ABS(J26)>5%),"O","") | M26: =E26-F26 -> 0
C27: 3. | D27: 타계정에서대체-제품 | G27: =F27*12/9 -> 0 | I27: =G27-H27 -> 0 | J27: =IFERROR(I27/H27,IF(I27>0,100%,IF(I27=0,0,-100%))) -> 0 | K27: =IF(AND(ABS(I27)>$K$5,ABS(J27)>5%),"O","") | M27: =E27-F27 -> 0
D28: 계 | E28: =SUM(E24:E27) -> 0 | F28: =SUM(F24:F27) -> 0 | G28: =F28*12/9 -> 0 | H28: =SUM(H24:H27) -> 0 | I28: =G28-H28 -> 0 | J28: =IFERROR(I28/H28,IF(I28>0,100%,IF(I28=0,0,-100%))) -> 0 | K28: =IF(AND(ABS(I28)>$K$5,ABS(J28)>5%),"O","") | M28: =E28-F28 -> 0 | U28: =SUM(U24:U27) -> 0 | V28: =E28-U28 -> 0 | W28: =SUM(W24:W27) -> 0 | X28: =F28-W28 -> 0
C29: 4. | D29: 타계정으로대체-제품 | G29: =F29*12/9 -> 0 | I29: =G29-H29 -> 0 | J29: =IFERROR(I29/H29,IF(I29>0,100%,IF(I29=0,0,-100%))) -> 0 | K29: =IF(AND(ABS(I29)>$K$5,ABS(J29)>5%),"O","") | M29: =E29-F29 -> 0
C30: 5. | D30: 기말제품재고액 | G30: =F30*12/9 -> 0 | I30: =G30-H30 -> 0 | J30: =IFERROR(I30/H30,IF(I30>0,100%,IF(I30=0,0,-100%))) -> 0 | K30: =IF(AND(ABS(I30)>$K$5,ABS(J30)>5%),"O","") | M30: =E30-F30 -> 0
C31: (3) | D31: 용역원가 | E31: =SUMIF(FS_map!$H:$H,$D31,FS_map!$M:$M) -> 0 | F31: =SUMIF(FS_map!$H:$H,$D31,FS_map!$P:$P) -> 0 | G31: =F31*12/9 -> 0 | H31: =WPL_2025YE!AI17 -> 0 | I31: =G31-H31 -> 0 | J31: =IFERROR(I31/H31,IF(I31>0,100%,IF(I31=0,0,-100%))) -> 0 | K31: =IF(AND(ABS(I31)>$K$5,ABS(J31)>5%),"O","") | M31: =E31-F31 -> 0 | N31: =IFERROR(+F31/F12,0) -> 0 | O31: =IFERROR(+H31/H12,0) -> 0 | U31: =SUMIF('PL_DEC.2026'!$D:$D,$D31,'PL_DEC.2026'!$E:$E) -> 0 | V31: =E31-U31 -> 0 | W31: =SUMIF('PL_DEC.2026'!$D:$D,$D31,'PL_DEC.2026'!$L:$L) -> 0 | X31: =F31-W31 -> 0
C32: III. 매출총이익 | E32: =+E10-E13 -> 130957736686 | F32: =+F10-F13 -> 130957736686 | G32: =F32*12/9 -> 1.7461032e+11 | H32: =+H10-H13 -> 144052198124 | I32: =G32-H32 -> 3.0558117e+10 | J32: =IFERROR(I32/H32,IF(I32>0,100%,IF(I32=0,0,-100%))) -> 0.21213225 | M32: =E32-F32 -> 0 | U32: =+U10-U13 -> 130957736686 | V32: =E32-U32 -> 0 | W32: =+W10-W13 -> 130549693661 | X32: =F32-W32 -> 408043025
C33: IV. 판매비와일반관리비 | E33: =E34+E40+E48+E74 -> 90107200362 | F33: =F34+F40+F48+F74 -> 69362864046 | G33: =F33*12/9 -> 92483818728 | H33: =H34+H40+H48+H74 -> 114570413852 | I33: =G33-H33 -> -22086595124 | J33: =IFERROR(I33/H33,IF(I33>0,100%,IF(I33=0,0,-100%))) -> -0.19277748 | M33: =E33-F33 -> 20744336316 | U33: =U34+U40+U48+U74 -> 90107200362 | V33: =E33-U33 -> 0 | W33: =W34+W40+W48+W74 -> 69362864046 | X33: =F33-W33 -> 0
C34: (1) 판매직접비 | E34: =SUM(E35:E39) -> 15965818075 | F34: =SUM(F35:F39) -> 15958336946 | G34: =F34*12/9 -> 2.1277783e+10 | H34: =SUM(H35:H39) -> 24336799235 | I34: =G34-H34 -> -3.0590166e+09 | J34: =IFERROR(I34/H34,IF(I34>0,100%,IF(I34=0,0,-100%))) -> -0.12569511 | K34: =IF(AND(ABS(I34)>$K$5,ABS(J34)>5%),"O","") | M34: =E34-F34 -> 7481129 | U34: =SUM(U35:U39) -> 15965818075 | V34: =E34-U34 -> 0 | W34: =SUM(W35:W39) -> 15958336946 | X34: =F34-W34 -> 0
C35: 1. | D35: 판매수당 | E35: =SUMIF(FS_map!$H:$H,$D35,FS_map!$M:$M) -> 3354728043 | F35: =SUMIF(FS_map!$H:$H,$D35,FS_map!$P:$P) -> 3354728043 | G35: =F35*12/9 -> 4472970724 | H35: =SUMIF(WPL_2025YE!$D:$D,$D35,WPL_2025YE!$AI:$AI) -> 4150097232 | I35: =G35-H35 -> 322873492 | J35: =IFERROR(I35/H35,IF(I35>0,100%,IF(I35=0,0,-100%))) -> 0.077799019 | K35: =IF(AND(ABS(I35)>$K$5,ABS(J35)>5%),"O","") | L35: 9월 누적 33.5억원 (전년 동기 32.4억원) 1. 영업 인센티브 지급 41.6억원 (전기 연간 41.7억원) 2. 충당금 −8.1억원: 24년분 영업인센티브 3.8억원(3월)과 25년분 8억원(7월)을 손익으로 환입 | M35: =E35-F35 -> 0 | U35: =SUMIF('PL_DEC.2026'!$D:$D,$D35,'PL_DEC.2026'!$E:$E) -> 3354728043 | V35: =E35-U35 -> 0 | W35: =SUMIF('PL_DEC.2026'!$D:$D,$D35,'PL_DEC.2026'!$L:$L) -> 3354728043 | X35: =F35-W35 -> 0
C36: 2. | D36: 판매촉진비 | E36: =SUMIF(FS_map!$H:$H,$D36,FS_map!$M:$M) -> 0 | F36: =SUMIF(FS_map!$H:$H,$D36,FS_map!$P:$P) -> 0 | G36: =F36*12/9 -> 0 | H36: =SUMIF(WPL_2025YE!$D:$D,$D36,WPL_2025YE!$AI:$AI) -> 0 | I36: =G36-H36 -> 0 | J36: =IFERROR(I36/H36,IF(I36>0,100%,IF(I36=0,0,-100%))) -> 0 | K36: =IF(AND(ABS(I36)>$K$5,ABS(J36)>5%),"O","") | M36: =E36-F36 -> 0 | U36: =SUMIF('PL_DEC.2026'!$D:$D,$D36,'PL_DEC.2026'!$E:$E) -> 0 | V36: =E36-U36 -> 0 | W36: =SUMIF('PL_DEC.2026'!$D:$D,$D36,'PL_DEC.2026'!$L:$L) -> 0 | X36: =F36-W36 -> 0
C37: 3. | D37: 하조및운임 | E37: =SUMIF(FS_map!$H:$H,$D37,FS_map!$M:$M) -> 1641883650 | F37: =SUMIF(FS_map!$H:$H,$D37,FS_map!$P:$P) -> 1641883650 | G37: =F37*12/9 -> 2189178200 | H37: =SUMIF(WPL_2025YE!$D:$D,$D37,WPL_2025YE!$AI:$AI) -> 2701698214 | I37: =G37-H37 -> -512520014 | J37: =IFERROR(I37/H37,IF(I37>0,100%,IF(I37=0,0,-100%))) -> -0.18970291 | K37: =IF(AND(ABS(I37)>$K$5,ABS(J37)>5%),"O","") | L37: 9월 누적 16.4억원 (전년 동기 18.7억원). 운송비 8.8억원 (전기 연간 18.2억원), 외부보관료 7.6억원 (전기 연간 12.2억원) | M37: =E37-F37 -> 0 | U37: =SUMIF('PL_DEC.2026'!$D:$D,$D37,'PL_DEC.2026'!$E:$E) -> 1641883650 | V37: =E37-U37 -> 0 | W37: =SUMIF('PL_DEC.2026'!$D:$D,$D37,'PL_DEC.2026'!$L:$L) -> 1641883650 | X37: =F37-W37 -> 0
C38: 4. | D38: 시장개척비 | E38: =SUMIF(FS_map!$H:$H,$D38,FS_map!$M:$M) -> 0 | F38: =SUMIF(FS_map!$H:$H,$D38,FS_map!$P:$P) -> 0 | G38: =F38*12/9 -> 0 | H38: =SUMIF(WPL_2025YE!$D:$D,$D38,WPL_2025YE!$AI:$AI) -> 0 | I38: =G38-H38 -> 0 | J38: =IFERROR(I38/H38,IF(I38>0,100%,IF(I38=0,0,-100%))) -> 0 | K38: =IF(AND(ABS(I38)>$K$5,ABS(J38)>5%),"O","") | M38: =E38-F38 -> 0 | U38: =SUMIF('PL_DEC.2026'!$D:$D,$D38,'PL_DEC.2026'!$E:$E) -> 0 | V38: =E38-U38 -> 0 | W38: =SUMIF('PL_DEC.2026'!$D:$D,$D38,'PL_DEC.2026'!$L:$L) -> 0 | X38: =F38-W38 -> 0
C39: 5. | D39: 광고선전비 | E39: =SUMIF(FS_map!$H:$H,$D39,FS_map!$M:$M) -> 10969206382 | F39: =SUMIF(FS_map!$H:$H,$D39,FS_map!$P:$P) -> 10961725253 | G39: =F39*12/9 -> 1.4615634e+10 | H39: =SUMIF(WPL_2025YE!$D:$D,$D39,WPL_2025YE!$AI:$AI) -> 17485003789 | I39: =G39-H39 -> -2.8693701e+09 | J39: =IFERROR(I39/H39,IF(I39>0,100%,IF(I39=0,0,-100%))) -> -0.16410463 | K39: =IF(AND(ABS(I39)>$K$5,ABS(J39)>5%),"O","") | L39: 9월 누적 110억원 (전년 동기 122억원 대비 −12억원) 1. Pharma A&P 감소: EP·희귀질환 판촉활동 축소, 항암 사업 divestment, 활동 지연 2. 백신은 전년 RSV 출시 관련 조기 집행 효과가 소멸 3. 주요 계정 (전기 연간 → 당기 9월 누적): PR비 42억 → 22억원, 후원비 26억 → 14억원, 외부행사 34억 → 23억원 | M39: =E39-F39 -> 7481129 | U39: =SUMIF('PL_DEC.2026'!$D:$D,$D39,'PL_DEC.2026'!$E:$E) -> 10969206382 | V39: =E39-U39 -> 0 | W39: =SUMIF('PL_DEC.2026'!$D:$D,$D39,'PL_DEC.2026'!$L:$L) -> 10961725253 | X39: =F39-W39 -> 0
C40: (2) 인건비 | E40: =SUM(E41:E47) -> 34547108797 | F40: =SUM(F41:F47) -> 31494645340 | G40: =F40*12/9 -> 4.199286e+10 | H40: =SUM(H41:H47) -> 59889099005 | I40: =G40-H40 -> -1.7896239e+10 | J40: =IFERROR(I40/H40,IF(I40>0,100%,IF(I40=0,0,-100%))) -> -0.29882297 | M40: =E40-F40 -> 3052463457 | U40: =SUM(U41:U47) -> 34547108797 | V40: =E40-U40 -> 0 | W40: =SUM(W41:W47) -> 31494645340 | X40: =F40-W40 -> 0
C41: 1. | D41: 임원급여 | E41: =SUMIF(FS_map!$H:$H,$D41,FS_map!$M:$M) -> 0 | F41: =SUMIF(FS_map!$H:$H,$D41,FS_map!$P:$P) -> 0 | G41: =F41*12/9 -> 0 | H41: =SUMIF(WPL_2025YE!$D:$D,$D41,WPL_2025YE!$AI:$AI) -> 0 | I41: =G41-H41 -> 0 | J41: =IFERROR(I41/H41,IF(I41>0,100%,IF(I41=0,0,-100%))) -> 0 | K41: =IF(AND(ABS(I41)>$K$5,ABS(J41)>5%),"O","") | M41: =E41-F41 -> 0 | U41: =SUMIF('PL_DEC.2026'!$D:$D,$D41,'PL_DEC.2026'!$E:$E) -> 0 | V41: =E41-U41 -> 0 | W41: =SUMIF('PL_DEC.2026'!$D:$D,$D41,'PL_DEC.2026'!$L:$L) -> 0 | X41: =F41-W41 -> 0
C42: 2. | D42: 급여 | E42: =SUMIF(FS_map!$H:$H,$D42,FS_map!$M:$M) -> 27029848823 | F42: =SUMIF(FS_map!$H:$H,$D42,FS_map!$P:$P) -> 24660200591 | G42: =F42*12/9 -> 3.2880267e+10 | H42: =SUMIF(WPL_2025YE!$D:$D,$D42,WPL_2025YE!$AI:$AI) -> 51357142027 | I42: =G42-H42 -> -1.8476875e+10 | J42: =IFERROR(I42/H42,IF(I42>0,100%,IF(I42=0,0,-100%))) -> -0.35977225 | K42: =IF(AND(ABS(I42)>$K$5,ABS(J42)>5%),"O","") -> O | L42: 9월 누적 247억원 (전년 동기 273억원), 연환산 329억원으로 전기 514억원 대비 −185억원 1. 전기 급여에는 Drive 구조조정 관련 명예퇴직 충당금 166억원(70051000)이 포함됨. 당기는 −14억원 순환입 (전기 Drive 구조조정 충당금 초과분 환입, GSF 구조조정(Argo·DD&O 등) 신규 비용 반영) 2. 경상 급여(62000300) 9월 누적 276억원 (연환산 368억원, 전기 372억원): 영업인력 감소(전년 대비 −20명) 효과로 소폭 감소 3. CRU rebilling 비용차감 조정(statutory #2): 당기 23.7억원, 전기 연간 42.4억원 → 배분 기준 일관성 확인 필요 | M42: =E42-F42 -> 2369648232 | U42: =SUMIF('PL_DEC.2026'!$D:$D,$D42,'PL_DEC.2026'!$E:$E) -> 27029848823 | V42: =E42-U42 -> 0 | W42: =SUMIF('PL_DEC.2026'!$D:$D,$D42,'PL_DEC.2026'!$L:$L) -> 24660200591 | X42: =F42-W42 -> 0
...

Sheet FS_map
D2: SAP GL | E2: Description | F2: Type | G2: Type | H2: Local Class(결산보고서) | I2: English | J2: (01.2026-09.2026) SAP | K2: Debit | L2: Credit | M2: 수정전 | N2: Debit | O2: Credit | P2: 수정후 | Q2: 2025.12 SAP(YTD) | R2: Source | S2: 회사 매핑 (BSPL2026 M열) | T2: 매핑 check
D3: 10100082 | E3: Lands and Buildings -Right of Use -Man | F3: BS | G3: 자산 | H3: 구축물 | I3: Lands and Buildings -Right of use (Man) | J3: =IFERROR(VLOOKUP(VALUE($D3),BSPL2026!$B:$Z,25,FALSE()),0) -> 12060074810 | M3: =J3+K3-L3 -> 12060074810 | N3: =SUMIF('statutory adj_2026 조정분개'!$S:$S,$D3,'statutory adj_2026 조정분개'!$K:$K) -> 0 | O3: =SUMIF('statutory adj_2026 조정분개'!$S:$S,$D3,'statutory adj_2026 조정분개'!$L:$L) -> 0 | P3: =M3+N3-O3 -> 12060074810 | Q3: =IFERROR(VLOOKUP(VALUE($D3),BSPL2026!$B:$Q,16,FALSE()),0) -> 12060074810 | R3: from BSPL2026 | S3: =IFERROR(VLOOKUP(VALUE($D3),BSPL2026!$B:$M,12,FALSE()),"") -> 구축물 | T3: =IF(OR(S3="",S3=0,LEFT(S3,5)="(원본오류"),"",IF(S3=H3,"","매핑차이"))
D4: 10100083 | E4: Depreciation Land and Build -Right of Use -Man | F4: BS | G4: 자산 | H4: 감가상각누계액-구축물 | I4: Acc.dep.Land and Build.-Right (Man) | J4: =IFERROR(VLOOKUP(VALUE($D4),BSPL2026!$B:$Z,25,FALSE()),0) -> -11842919020 | M4: =J4+K4-L4 -> -11842919020 | N4: =SUMIF('statutory adj_2026 조정분개'!$S:$S,$D4,'statutory adj_2026 조정분개'!$K:$K) -> 0 | O4: =SUMIF('statutory adj_2026 조정분개'!$S:$S,$D4,'statutory adj_2026 조정분개'!$L:$L) -> 0 | P4: =M4+N4-O4 -> -11842919020 | Q4: =IFERROR(VLOOKUP(VALUE($D4),BSPL2026!$B:$Q,16,FALSE()),0) -> -10865717938 | R4: from BSPL2026 | S4: =IFERROR(VLOOKUP(VALUE($D4),BSPL2026!$B:$M,12,FALSE()),"") -> 감가상각누계액-구축물 | T4: =IF(OR(S4="",S4=0,LEFT(S4,5)="(원본오류"),"",IF(S4=H4,"","매핑차이"))
D5: 10100850 | E5: Buildings -(A) Rec | F5: BS | G5: 자산 | H5: 구축물 | I5: Structures | J5: =IFERROR(VLOOKUP(VALUE($D5),BSPL2026!$B:$Z,25,FALSE()),0) -> 239169200 | M5: =J5+K5-L5 -> 239169200 | N5: =SUMIF('statutory adj_2026 조정분개'!$S:$S,$D5,'statutory adj_2026 조정분개'!$K:$K) -> 0 | O5: =SUMIF('statutory adj_2026 조정분개'!$S:$S,$D5,'statutory adj_2026 조정분개'!$L:$L) -> 0 | P5: =M5+N5-O5 -> 239169200 | Q5: =IFERROR(VLOOKUP(VALUE($D5),BSPL2026!$B:$Q,16,FALSE()),0) -> 239169200 | R5: from BSPL2026 | S5: =IFERROR(VLOOKUP(VALUE($D5),BSPL2026!$B:$M,12,FALSE()),"") -> 구축물 | T5: =IF(OR(S5="",S5=0,LEFT(S5,5)="(원본오류"),"",IF(S5=H5,"","매핑차이"))
D6: 10150000 | E6: Buildings -Leasehold Improvements -(A) Rec | F6: BS | G6: 자산 | H6: 구축물 | I6: Depreciation Buildings -Leasehold Improve -(A) Rec | J6: =IFERROR(VLOOKUP(VALUE($D6),BSPL2026!$B:$Z,25,FALSE()),0) -> 1304901001 | M6: =J6+K6-L6 -> 1304901001 | N6: =SUMIF('statutory adj_2026 조정분개'!$S:$S,$D6,'statutory adj_2026 조정분개'!$K:$K) -> 0 | O6: =SUMIF('statutory adj_2026 조정분개'!$S:$S,$D6,'statutory adj_2026 조정분개'!$L:$L) -> 0 | P6: =M6+N6-O6 -> 1304901001 | Q6: =IFERROR(VLOOKUP(VALUE($D6),BSPL2026!$B:$Q,16,FALSE()),0) -> 1304901001 | R6: from BSPL2026 | S6: =IFERROR(VLOOKUP(VALUE($D6),BSPL2026!$B:$M,12,FALSE()),"") -> 구축물 | T6: =IF(OR(S6="",S6=0,LEFT(S6,5)="(원본오류"),"",IF(S6=H6,"","매핑차이"))
D7: 10200000 | E7: Machinery and Equipment -(A) Rec | F7: BS | G7: 자산 | H7: 기계장치 | I7: Plant & Machinery | J7: =IFERROR(VLOOKUP(VALUE($D7),BSPL2026!$B:$Z,25,FALSE()),0) -> 1434004742 | M7: =J7+K7-L7 -> 1434004742 | N7: =SUMIF('statutory adj_2026 조정분개'!$S:$S,$D7,'statutory adj_2026 조정분개'!$K:$K) -> 0 | O7: =SUMIF('statutory adj_2026 조정분개'!$S:$S,$D7,'statutory adj_2026 조정분개'!$L:$L) -> 485029742 | P7: =M7+N7-O7 -> 948975000 | Q7: =IFERROR(VLOOKUP(VALUE($D7),BSPL2026!$B:$Q,16,FALSE()),0) -> 1434004742 | R7: from BSPL2026 | S7: =IFERROR(VLOOKUP(VALUE($D7),BSPL2026!$B:$M,12,FALSE()),"") -> 기계장치 | T7: =IF(OR(S7="",S7=0,LEFT(S7,5)="(원본오류"),"",IF(S7=H7,"","매핑차이"))
D8: 10200921 | E8: Samples -Manual | F8: BS | G8: 자산 | H8: 상품 | I8: Samples -Manual | J8: =IFERROR(VLOOKUP(VALUE($D8),BSPL2026!$B:$Z,25,FALSE()),0) -> 0 | M8: =J8+K8-L8 -> 0 | N8: =SUMIF('statutory adj_2026 조정분개'!$S:$S,$D8,'statutory adj_2026 조정분개'!$K:$K) -> 0 | O8: =SUMIF('statutory adj_2026 조정분개'!$S:$S,$D8,'statutory adj_2026 조정분개'!$L:$L) -> 0 | P8: =M8+N8-O8 -> 0 | Q8: =IFERROR(VLOOKUP(VALUE($D8),BSPL2026!$B:$Q,16,FALSE()),0) -> 0 | R8: from BSPL2026 | S8: =IFERROR(VLOOKUP(VALUE($D8),BSPL2026!$B:$M,12,FALSE()),"") -> 상품 | T8: =IF(OR(S8="",S8=0,LEFT(S8,5)="(원본오류"),"",IF(S8=H8,"","매핑차이"))
D9: 10300000 | E9: Other FA -Furniture Fixtures & Office Equ -(A) Rec | F9: BS | G9: 자산 | H9: 집기비품 | I9: Furniture/Fittings/Office Equipment | J9: =IFERROR(VLOOKUP(VALUE($D9),BSPL2026!$B:$Z,25,FALSE()),0) -> 350199634 | M9: =J9+K9-L9 -> 350199634 | N9: =SUMIF('statutory adj_2026 조정분개'!$S:$S,$D9,'statutory adj_2026 조정분개'!$K:$K) -> 0 | O9: =SUMIF('statutory adj_2026 조정분개'!$S:$S,$D9,'statutory adj_2026 조정분개'!$L:$L) -> 0 | P9: =M9+N9-O9 -> 350199634 | Q9: =IFERROR(VLOOKUP(VALUE($D9),BSPL2026!$B:$Q,16,FALSE()),0) -> 350199634 | R9: from BSPL2026 | S9: =IFERROR(VLOOKUP(VALUE($D9),BSPL2026!$B:$M,12,FALSE()),"") -> 집기비품 | T9: =IF(OR(S9="",S9=0,LEFT(S9,5)="(원본오류"),"",IF(S9=H9,"","매핑차이"))
D10: 10300850 | E10: Other Fixed Assets -(A) Rec | F10: BS | G10: 자산 | H10: 공구와기구 | I10: Other Tools and Furniture | J10: =IFERROR(VLOOKUP(VALUE($D10),BSPL2026!$B:$Z,25,FALSE()),0) -> 42938000 | M10: =J10+K10-L10 -> 42938000 | N10: =SUMIF('statutory adj_2026 조정분개'!$S:$S,$D10,'statutory adj_2026 조정분개'!$K:$K) -> 485029742 | O10: =SUMIF('statutory adj_2026 조정분개'!$S:$S,$D10,'statutory adj_2026 조정분개'!$L:$L) -> 0 | P10: =M10+N10-O10 -> 527967742 | Q10: =IFERROR(VLOOKUP(VALUE($D10),BSPL2026!$B:$Q,16,FALSE()),0) -> 42938000 | R10: from BSPL2026 | S10: =IFERROR(VLOOKUP(VALUE($D10),BSPL2026!$B:$M,12,FALSE()),"") -> 공구와기구 | T10: =IF(OR(S10="",S10=0,LEFT(S10,5)="(원본오류"),"",IF(S10=H10,"","매핑차이"))
D11: 10350000 | E11: Other FA -IT Equipment -(A) Rec | F11: BS | G11: 자산 | H11: 집기비품 | I11: EDP Equipment | J11: =IFERROR(VLOOKUP(VALUE($D11),BSPL2026!$B:$Z,25,FALSE()),0) -> 1369225145 | M11: =J11+K11-L11 -> 1369225145 | N11: =SUMIF('statutory adj_2026 조정분개'!$S:$S,$D11,'statutory adj_2026 조정분개'!$K:$K) -> 0 | O11: =SUMIF('statutory adj_2026 조정분개'!$S:$S,$D11,'statutory adj_2026 조정분개'!$L:$L) -> 0 | P11: =M11+N11-O11 -> 1369225145 | Q11: =IFERROR(VLOOKUP(VALUE($D11),BSPL2026!$B:$Q,16,FALSE()),0) -> 1282738705 | R11: from BSPL2026 | S11: =IFERROR(VLOOKUP(VALUE($D11),BSPL2026!$B:$M,12,FALSE()),"") -> 집기비품 | T11: =IF(OR(S11="",S11=0,LEFT(S11,5)="(원본오류"),"",IF(S11=H11,"","매핑차이"))
D12: 10350303 | E12: Other Fixed Assets -(A) Rec | F12: BS | G12: 자산 | H12: 공구와기구 | I12: Depreciation Other Fixed Assets -(A) Rec | J12: =IFERROR(VLOOKUP(VALUE($D12),BSPL2026!$B:$Z,25,FALSE()),0) -> 34046016 | M12: =J12+K12-L12 -> 34046016 | N12: =SUMIF('statutory adj_2026 조정분개'!$S:$S,$D12,'statutory adj_2026 조정분개'!$K:$K) -> 0 | O12: =SUMIF('statutory adj_2026 조정분개'!$S:$S,$D12,'statutory adj_2026 조정분개'!$L:$L) -> 0 | P12: =M12+N12-O12 -> 34046016 | Q12: =IFERROR(VLOOKUP(VALUE($D12),BSPL2026!$B:$Q,16,FALSE()),0) -> 34046016 | R12: from BSPL2026 | S12: =IFERROR(VLOOKUP(VALUE($D12),BSPL2026!$B:$M,12,FALSE()),"") -> 공구와기구 | T12: =IF(OR(S12="",S12=0,LEFT(S12,5)="(원본오류"),"",IF(S12=H12,"","매핑차이"))
D13: 10550400 | E13: In Progress -Other -IT Equipment -(A) | F13: BS | G13: 자산 | H13: 소프트웨어 | I13: In Progress -Other -IT Equipment -(A) | J13: =IFERROR(VLOOKUP(VALUE($D13),BSPL2026!$B:$Z,25,FALSE()),0) -> 22468609 | M13: =J13+K13-L13 -> 22468609 | N13: =SUMIF('statutory adj_2026 조정분개'!$S:$S,$D13,'statutory adj_2026 조정분개'!$K:$K) -> 0 | O13: =SUMIF('statutory adj_2026 조정분개'!$S:$S,$D13,'statutory adj_2026 조정분개'!$L:$L) -> 0 | P13: =M13+N13-O13 -> 22468609 | Q13: =IFERROR(VLOOKUP(VALUE($D13),BSPL2026!$B:$Q,16,FALSE()),0) -> 0 | R13: from BSPL2026 | S13: =IFERROR(VLOOKUP(VALUE($D13),BSPL2026!$B:$M,12,FALSE()),"") -> 소프트웨어 | T13: =IF(OR(S13="",S13=0,LEFT(S13,5)="(원본오류"),"",IF(S13=H13,"","매핑차이"))
D14: 10550900 | E14: In Progress -Buildings -(A) Rec | F14: BS | G14: 자산 | H14: 건설중인자산 | I14: Const.in Process | J14: =IFERROR(VLOOKUP(VALUE($D14),BSPL2026!$B:$Z,25,FALSE()),0) -> 51562836 | M14: =J14+K14-L14 -> 51562836 | N14: =SUMIF('statutory adj_2026 조정분개'!$S:$S,$D14,'statutory adj_2026 조정분개'!$K:$K) -> 0 | O14: =SUMIF('statutory adj_2026 조정분개'!$S:$S,$D14,'statutory adj_2026 조정분개'!$L:$L) -> 0 | P14: =M14+N14-O14 -> 51562836 | Q14: =IFERROR(VLOOKUP(VALUE($D14),BSPL2026!$B:$Q,16,FALSE()),0) -> 8237836 | R14: from BSPL2026 | S14: =IFERROR(VLOOKUP(VALUE($D14),BSPL2026!$B:$M,12,FALSE()),"") -> 건설중인자산 | T14: =IF(OR(S14="",S14=0,LEFT(S14,5)="(원본오류"),"",IF(S14=H14,"","매핑차이"))
... D444: 반품충당금비유동 | E444: 반품충당금(비유동) - statutory reclass 가상계정 | F444: BS | G444: 부채 | H444: 반품충당금 | I444: Provision for sales return (Non-current) | J444: =IFERROR(VLOOKUP(VALUE($D444),BSPL2026!$B:$Z,25,FALSE()),0) -> 0 | M444: =J444+K444-L444 -> 0 | N444: =SUMIF('statutory adj_2026 조정분개'!$S:$S,$D444,'statutory adj_2026 조정분개'!$K:$K) -> 0 | O444: =SUMIF('statutory adj_2026 조정분개'!$S:$S,$D444,'statutory adj_2026 조정분개'!$L:$L) -> 646256500 | P444: =M444+N444-O444 -> -646256500 | Q444: =IFERROR(VLOOKUP(VALUE($D444),BSPL2026!$B:$Q,16,FALSE()),0) -> 0 | R444: manual (statutory adj #3) | S444: =IFERROR(VLOOKUP(VALUE($D444),BSPL2026!$B:$M,12,FALSE()),"") | T444: =IF(OR(S444="",S444=0,LEFT(S444,5)="(원본오류"),"",IF(S444=H444,"","매핑차이"))
D445: Total | J445: =SUM(J3:J444) -> 0 | K445: =SUM(K3:K444) -> 0 | L445: =SUM(L3:L444) -> 0 | M445: =SUM(M3:M444) -> 0 | N445: =SUM(N3:N444) -> 36539768561 | O445: =SUM(O3:O444) -> 36539768561 | P445: =SUM(P3:P444) -> 0 | Q445: =SUM(Q3:Q444) -> 4
D446: check: 조정분개 반영대상 합계(S열 연결분) | N446: =N445-SUMPRODUCT(('statutory adj_2026 조정분개'!$S$7:$S$77<>"")*'statutory adj_2026 조정분개'!$K$7:$K$77) -> 0 | O446: =O445-SUMPRODUCT(('statutory adj_2026 조정분개'!$S$7:$S$77<>"")*'statutory adj_2026 조정분개'!$L$7:$L$77) -> 0
D447: check: 조정분개 전체 합계 대비(부가세 9원 미반영분) | N447: =N445-'statutory adj_2026 조정분개'!K78 -> -9 | O447: =O445-'statutory adj_2026 조정분개'!L78 -> -9
I449: BS | J449: =SUMIF($F$3:$F$444,I449,$J$3:$J$444) -> 49288887022 | O449: BS | P449: =SUMIF($F$3:$F$444,O449,$P$3:$P$444) -> 49288887022
I450: PL | J450: =SUMIF($F$3:$F$444,I450,$J$3:$J$444) -> -49288887022 | O450: PL | P450: =SUMIF($F$3:$F$444,O450,$P$3:$P$444) -> -49288887022
D452: 매핑차이 건수 | J452: =COUNTIF($T$3:$T$444,"매핑차이") -> 1
D453: 가계정(GR/IR) 잔액 – 0이어야 함 | J453: =SUMIF($H$3:$H$444,"가계정",$M$3:$M$444) -> 0
D454: BS_KO/P&L_KO 미집계 FS과목 건수 – 0이어야 함 | J454: =SUMPRODUCT(--($H$3:$H$444<>"가계정"),--($H$3:$H$444<>"제품매출원가"),--($H$3:$H$444<>"판매 및 일반관리비 대체"),--ISNA(MATCH($H$3:$H$444,BS_KO!$D$1:$D$130,0)),--ISNA(MATCH($H$3:$H$444,'P&L_KO'!$D$1:$D$120,0))) -> 0

Sheet statutory adj_2026 조정분개
Q1: 계정대체
I2: Summary of Statutory adjustment (2026)
P3: - 이익 / + 손실
C5: Current year effect adjustment - NOT BOOKED | H5: P16 ADJ
A6: SAP BOOKED? 2025.16 | B6: Reversal | F6: BSPL | G6: GL account | H6: GL account | K6: DR | L6: CR | M6: Asset | N6: Liability | O6: Equity | P6: P&L | S6: FS_map 연결 GL | T6: 비고(정산표 반영)
C7: 1 | D7: GL reclassification (보증금 중 회원권 구분 대체) | F7: BS | G7: 15800870 | H7: 86158008 | I7: 기타투자자산 | K7: 30000000 | M7: =++K7 -> 30000000 | S7: =IF(ISNUMBER(MATCH(G7&"",FS_map!$D:$D,0)),G7&"",IF(H7="","",H7&"")) -> 86158008 | T7: SAP GL 15800870 미존재 → P16 GL 86158008(기타의 투자자산) 사용
F8: BS | G8: 15800853 | H8: 86260033 | J8: 보증금 | L8: 30000000 | M8: =++-L8 -> -30000000 | S8: =IF(ISNUMBER(MATCH(G8&"",FS_map!$D:$D,0)),G8&"",IF(H8="","",H8&"")) -> 15800853
C11: 2 | D11: GL reclassification (CRU rebilling 비용차감대체) | F11: PL | G11: 74250001 | H11: 86200400 | I11: 잡이익 | K11: 20794942446 | P11: =++K11 -> 20794942446 | S11: =IF(ISNUMBER(MATCH(G11&"",FS_map!$D:$D,0)),G11&"",IF(H11="","",H11&"")) -> 74250001
F12: PL | G12: 86000300 | H12: 86000300 | J12: 급여 | L12: 2369648232 | P12: =++-L12 -> -2369648232 | S12: =IF(ISNUMBER(MATCH(G12&"",FS_map!$D:$D,0)),G12&"",IF(H12="","",H12&"")) -> 86000300
F13: PL | G13: 86000004 | H13: 86000004 | J13: 복리후생비 | L13: 155357637 | P13: =++-L13 -> -155357637 | S13: =IF(ISNUMBER(MATCH(G13&"",FS_map!$D:$D,0)),G13&"",IF(H13="","",H13&"")) -> 86000004
F14: PL | G14: 86400910 | H14: 86400910 | J14: 성과급여 | L14: 333409964 | P14: =++-L14 -> -333409964 | S14: =IF(ISNUMBER(MATCH(G14&"",FS_map!$D:$D,0)),G14&"",IF(H14="","",H14&"")) -> 86400910
F15: PL | G15: 86100747 | H15: 86100747 | J15: 퇴직급여 | L15: 349405261 | P15: =++-L15 -> -349405261 | S15: =IF(ISNUMBER(MATCH(G15&"",FS_map!$D:$D,0)),G15&"",IF(H15="","",H15&"")) -> 86100747
F16: PL | G16: 86000400 | H16: 86000400 | J16: 교육훈련비 | L16: 6474004 | P16: =++-L16 -> -6474004 | S16: =IF(ISNUMBER(MATCH(G16&"",FS_map!$D:$D,0)),G16&"",IF(H16="","",H16&"")) -> 86000400
F17: PL | G17: 86073501 | H17: 86073501 | J17: 임상증례조사비 | L17: 13314198758 | P17: =++-L17 -> -13314198758 | S17: =IF(ISNUMBER(MATCH(G17&"",FS_map!$D:$D,0)),G17&"",IF(H17="","",H17&"")) -> 86073501
F18: PL | G18: 86514001 | H18: 86514001 | J18: 광고선전비 | L18: 7481129 | P18: =++-L18 -> -7481129 | S18: =IF(ISNUMBER(MATCH(G18&"",FS_map!$D:$D,0)),G18&"",IF(H18="","",H18&"")) -> 86514001
F19: PL | G19: 86000006 | H19: 86000006 | J19: 여비교통비 | L19: 128225390 | P19: =++-L19 -> -128225390 | S19: =IF(ISNUMBER(MATCH(G19&"",FS_map!$D:$D,0)),G19&"",IF(H19="","",H19&"")) -> 86000006
F20: PL | G20: 86290000 | H20: 86290000 | J20: 지급수수료 | L20: 61682684 | P20: =++-L20 -> -61682684 | S20: =IF(ISNUMBER(MATCH(G20&"",FS_map!$D:$D,0)),G20&"",IF(H20="","",H20&"")) -> 86290000
F21: PL | G21: 86100925 | H21: 86100925 | J21: 보험료 | L21: 3977948983 | P21: =++-L21 -> -3977948983 | S21: =IF(ISNUMBER(MATCH(G21&"",FS_map!$D:$D,0)),G21&"",IF(H21="","",H21&"")) -> 86100925
F22: PL | G22: 86900000 | H22: 86900000 | J22: 통신비 | L22: 15020622 | P22: =++-L22 -> -15020622 | S22: =IF(ISNUMBER(MATCH(G22&"",FS_map!$D:$D,0)),G22&"",IF(H22="","",H22&"")) -> 86900000
F23: PL | G23: 86300510 | H23: 86300510 | J23: 소모품비 | L23: 17966376 | P23: =++-L23 -> -17966376 | S23: =IF(ISNUMBER(MATCH(G23&"",FS_map!$D:$D,0)),G23&"",IF(H23="","",H23&"")) -> 86300510
... F26: PL | G26: 86200400 | H26: 86200400 | J26: 잡이익 | L26: 50606130 | P26: =++-L26 -> -50606130 | S26: =IF(ISNUMBER(MATCH(G26&"",FS_map!$D:$D,0)),G26&"",IF(H26="","",H26&"")) -> 86200400
C28: 3 | D28: GL reclassification (반품충당금 유동->비 유동대체) | F28: BS | G28: 38010000 | H28: 86380100 | I28: 반품충당금유동 | K28: 646256500 | N28: =++K28 -> 646256500 | S28: =IF(ISNUMBER(MATCH(G28&"",FS_map!$D:$D,0)),G28&"",IF(H28="","",H28&"")) -> 38010000
F29: BS | G29: 반품충당금비유동 | H29: 86380100 | J29: 반품충당금비유동 | L29: =++K28 -> 646256500 | N29: =++-L29 -> -646256500 | S29: =IF(ISNUMBER(MATCH(G29&"",FS_map!$D:$D,0)),G29&"",IF(H29="","",H29&"")) -> 반품충당금비유동 | T29: FS_map 가상계정 "반품충당금비유동" 사용
C31: 5 | D31: GL reclass GTN 미지급비용 부채계상에서 매출채권에서 직접차감 | F31: BS | G31: 42910850 | H31: 86429108 | I31: 미지급비용 | K31: 758423387 | N31: =++K31 -> 758423387 | Q31: 미지급비용-미지급에누리 | S31: =IF(ISNUMBER(MATCH(G31&"",FS_map!$D:$D,0)),G31&"",IF(H31="","",H31&"")) -> 42910850
F32: BS | G32: 42910852 | H32: 86429108 | I32: 미지급비용 | K32: 10532431629 | N32: =++K32 -> 10532431629 | Q32: 미지급비용-미지급에누리 | S32: =IF(ISNUMBER(MATCH(G32&"",FS_map!$D:$D,0)),G32&"",IF(H32="","",H32&"")) -> 42910852
F33: BS | G33: 42910853 | H33: 86429108 | I33: 미지급비용 | K33: 1124955108 | N33: =++K33 -> 1124955108 | Q33: 미지급비용-미지급에누리 | S33: =IF(ISNUMBER(MATCH(G33&"",FS_map!$D:$D,0)),G33&"",IF(H33="","",H33&"")) -> 42910853
F34: BS | G34: 24000000 | H34: 86240007 | J34: 매출채권 | L34: =++K31+K32+K33 -> 12415810124 | M34: =++-L34 -> -12415810124 | Q34: 외상매출금-내수일반 | S34: =IF(ISNUMBER(MATCH(G34&"",FS_map!$D:$D,0)),G34&"",IF(H34="","",H34&"")) -> 24000000
C36: 6 | D36: GL reclassification (국민연금전환금 미수금 → 선급금) | F36: BS | G36: 26650000 | H36: 86260008 | I36: 선급금 | K36: 0 | M36: =++K36 -> 0 | S36: =IF(ISNUMBER(MATCH(G36&"",FS_map!$D:$D,0)),G36&"",IF(H36="","",H36&"")) -> 26650000
F37: BS | G37: 16350702 | H37: 86260033 | J37: Other receivables for employees | L37: =++K36 -> 0 | N37: =++-L37 -> 0 | S37: =IF(ISNUMBER(MATCH(G37&"",FS_map!$D:$D,0)),G37&"",IF(H37="","",H37&"")) -> 16350702
C40: 7 | D40: GL reclassification (기계장치 → 공기구비품_집기비품 대체) | F40: BS | G40: 10200000 | H40: 86102007 | I40: 기계장치 | L40: 485029742 | M40: =++-L40 -> -485029742 | S40: =IF(ISNUMBER(MATCH(G40&"",FS_map!$D:$D,0)),G40&"",IF(H40="","",H40&"")) -> 10200000
F41: BS | G41: 11200000 | H41: 86112007 | I41: 감가상각누계액-기계장치 | K41: 422529742 | M41: =++K41 -> 422529742 | S41: =IF(ISNUMBER(MATCH(G41&"",FS_map!$D:$D,0)),G41&"",IF(H41="","",H41&"")) -> 11200000
F42: BS | G42: 10300850 | H42: 86104100 | I42: 공구와기구 | K42: =++L40 -> 485029742 | M42: =++K42 -> 485029742 | S42: =IF(ISNUMBER(MATCH(G42&"",FS_map!$D:$D,0)),G42&"",IF(H42="","",H42&"")) -> 10300850
F43: BS | G43: 11300850 | H43: 86111500 | I43: 감가상각누계액-공구와기구 | L43: =++K41 -> 422529742 | M43: =++-L43 -> -422529742 | S43: =IF(ISNUMBER(MATCH(G43&"",FS_map!$D:$D,0)),G43&"",IF(H43="","",H43&"")) -> 11300850
C45: 8 | D45: GL reclassification (미지급비용 → 예수금) | F45: BS | G45: 42910000 | I45: 미지급비용 | L45: 612260090 | N45: =-L45 -> -612260090 | S45: =IF(ISNUMBER(MATCH(G45&"",FS_map!$D:$D,0)),G45&"",IF(H45="","",H45&"")) -> 42910000
D46: social security liab - 그룹리포팅과 SAP 매핑차이로 인한 월말 reclass | F46: BS | G46: 40000012 | I46: 미지급금 | K46: =L45 -> 612260090 | N46: =K46 -> 612260090 | S46: =IF(ISNUMBER(MATCH(G46&"",FS_map!$D:$D,0)),G46&"",IF(H46="","",H46&"")) -> 40000012
A49: BOOKED P16 | B49: 2026.02 | C49: =C45+1 -> 9 | D49: 205년 CRU rebilling True-up (2월에 확정) | F49: PL | G49: 74250001 | H49: 86200400 | I49: 잡이익 | L49: 0 | P49: =++-L49 -> 0 | S49: =IF(ISNUMBER(MATCH(G49&"",FS_map!$D:$D,0)),G49&"",IF(H49="","",H49&"")) -> 74250001
F50: BS | G50: 26050000 | H50: 86260033 | J50: 미수금 | K50: =++L49 -> 0 | N50: =++K50 -> 0 | S50: =IF(ISNUMBER(MATCH(G50&"",FS_map!$D:$D,0)),G50&"",IF(H50="","",H50&"")) -> 26050000
A52: BOOKED P16 | B52: 2026.02 | C52: 10 | D52: 25년 TP Adjustment (2월 확정 금액) | F52: PL | G52: 53000005 | H52: 86000800 | I52: 매출원가 | K52: 0 | P52: =++K52 -> 0 | Q52: 2025.12 invoice/credit 홀딩됨 | S52: =IF(ISNUMBER(MATCH(G52&"",FS_map!$D:$D,0)),G52&"",IF(H52="","",H52&"")) -> 53000005
D53: Statutory: 매출원가로 인식 | F53: BS | G53: 40100000 | H53: 86429100 | J53: 매입채무 | L53: =++K52 -> 0 | N53: =++-L53 -> 0 | Q53: 2025.12 invoice/credit 홀딩됨 | S53: =IF(ISNUMBER(MATCH(G53&"",FS_map!$D:$D,0)),G53&"",IF(H53="","",H53&"")) -> 40100000
D54: Internal: 잡손실/잡이익
...

Sheet BSPL2026
L1: Vlookup | M1: Vlookup | N1: SAP | O1: SAP | P1: SAP | Q1: 2025.12 | R1: 2026.01 | S1: 2026.02 | T1: 2026.03 | U1: 2026.04 | V1: 2026.05 | W1: 2026.06 | X1: 2026.07 | Y1: 2026.08 | Z1: 2026.09 | AE1: 2026.01 | AF1: 2026.02 | AG1: 2025.03 | AH1: 2025.04 | AI1: 2025.05 | AJ1: 2025.06 | AK1: 2025.07 | AL1: 2025.08 | AM1: 2025.09 | AN1: 2025.10 | AO1: 2025.11 | AP1: 2025.12
A2: BS/PL | B2: Account Number | C2: Text for B/S P&L item | D2: SAP Description | E2: SAP Description 2 | F2: Type | G2: Account Group | H2: Company Code | I2: Group account number | J2: CC driven | K2: Group account description | L2: 감사보고서 과목 1 | M2: 감사보고서 과목 2 | N2: Internal BookKR 구분 | O2: Internal Book KR 구분 | P2: Internal Book KR 구분 | Q2: YTD Dec 2025 | R2: YTD Jan 2026 | S2: YTD Feb 2026 | T2: YTD Mar 2026 | U2: YTD April 2026 | V2: YTD May 2026 | W2: YTD June 2026 | X2: YTD July 2026 | Y2: YTD Aug 2026 | Z2: YTD Sep 2026 | AA2: YTD Sep 2026 | AB2: YTD Oct 2026 | AC2: YTD Nov 2026 | AD2: YTD Dec 2026 | AE2: MTD Jan 2026 | AF2: MTD Feb 2026 | AG2: MTD Mar 2025 | AH2: MTD Apr 2025 | AI2: MTD May 2025 | AJ2: MTD June 2025 | AK2: MTD July 2025 | AL2: MTD Aug 2025 | AM2: MTD Sep 2025 | AN2: MTD Oct 2025 | AO2: MTD Nov 2025 | AP2: MTD Dec 2025
A3: + | B3: + | C3: + | D3: + | E3: + | F3: + | G3: + | H3: + | I3: + | J3: + | K3: + | L3: + | M3: + | Q3: + | R3: + | S3: + | T3: + | U3: + | V3: + | W3: + | X3: + | Y3: + | Z3: + | AA3: + | AB3: + | AC3: + | AD3: + | AE3: + | AF3: + | AG3: + | AH3: + | AI3: + | AJ3: + | AK3: + | AL3: + | AM3: + | AN3: + | AO3: + | AP3: + | AQ3: +
A4: BS | B4: 10100082 | C4: 10100082 Lands and Buildings -Right of Use -Man | D4: ¥±. NON-CURRENT ASSETS | E4: (2) Tangible assets | F4: 2. Buildings | G4: 01. NCA - Non Current Assets | H4: 1616 | I4: 10035 | K4: Lands and buildings - Right of use | L4: 자산 | M4: 구축물 | N4: 자산 | O4: 비유동자산 | P4: 구축물 | Q4: 12060074810 | R4: 12060074810 | S4: 12060074810 | T4: 12060074810 | U4: 12060074810 | V4: 12060074810 | W4: 12060074810 | X4: 12060074810 | Y4: 12060074810 | Z4: 12060074810 | AE4: =R4 -> 12060074810 | AF4: =S4-R4 -> 0 | AG4: =T4-S4 -> 0 | AH4: =U4-T4 -> 0 | AI4: =V4-U4 -> 0 | AJ4: =W4-V4 -> 0 | AK4: =X4-W4 -> 0 | AL4: =Y4-X4 -> 0 | AM4: =Z4-Y4 -> 0
A5: BS | B5: 10100083 | C5: 10100083 Depreciation Land and Build -Right of Use -Man | D5: ¥±. NON-CURRENT ASSETS | E5: (2) Tangible assets | F5: Accumulated depreciation | G5: 01. NCA - Non Current Assets | H5: 1616 | I5: 10115 | K5: Depreciation - Lands and buildings - Right of use | L5: 자산 | M5: 감가상각누계액-구축물 | N5: 자산 | O5: 비유동자산 | P5: 감가상각누계액-구축물 | Q5: -10865717938 | R5: -10974295836 | S5: -11082873734 | T5: -11191451632 | U5: -11300029530 | V5: -11408607428 | W5: -11517185326 | X5: -11625763224 | Y5: -11720034754 | Z5: -11842919020 | AE5: =R5 -> -10974295836 | AF5: =S5-R5 -> -108577898 | AG5: =T5-S5 -> -108577898 | AH5: =U5-T5 -> -108577898 | AI5: =V5-U5 -> -108577898 | AJ5: =W5-V5 -> -108577898 | AK5: =X5-W5 -> -108577898 | AL5: =Y5-X5 -> -94271530 | AM5: =Z5-Y5 -> -122884266 | AR5: =IFERROR(VLOOKUP(M5,'BS_DEC 2026'!$D$12:$D$109,1,FALSE()),"(미존재)") -> 감가상각누계액-구축물
